[2024-01-08 17:42:06] [INFO    ] discord.client: logging in using static token
[2024-01-08 17:42:07] [INFO    ] discord.gateway: Shard ID None has connected to Gateway (Session ID: a6ec5b4957ea8b65979aa7284e2c668e).
[2024-01-08 17:42:09] [INFO    ] root: Bot is ready.
[2024-01-08 18:18:02] [INFO    ] discord.client: logging in using static token
[2024-01-08 18:18:03] [INFO    ] discord.gateway: Shard ID None has connected to Gateway (Session ID: fe82e07abc50bbae5e46ec085244431b).
[2024-01-08 18:18:05] [INFO    ] root: Bot is ready.
[2024-01-08 18:18:24] [ERROR   ] discord.app_commands.tree: Ignoring exception in command 'ssss'
Traceback (most recent call last):
  File "/home/sild/.local/lib/python3.10/site-packages/discord/app_commands/tree.py", line 1248, in _call
    await command._invoke_with_namespace(interaction, namespace)
  File "/home/sild/.local/lib/python3.10/site-packages/discord/app_commands/commands.py", line 852, in _invoke_with_namespace
    transformed_values = await self._transform_arguments(interaction, namespace)
  File "/home/sild/.local/lib/python3.10/site-packages/discord/app_commands/commands.py", line 816, in _transform_arguments
    raise CommandSignatureMismatch(self) from None
discord.app_commands.errors.CommandSignatureMismatch: The signature for command 'ssss' is different from the one provided by Discord. This can happen because either your code is out of date or you have not synced the commands with Discord, causing the mismatch in data. It is recommended to sync the command tree to fix this issue.
[2024-01-08 18:18:40] [ERROR   ] discord.app_commands.tree: Ignoring exception in command 'ssss'
Traceback (most recent call last):
  File "/home/sild/.local/lib/python3.10/site-packages/discord/app_commands/tree.py", line 1248, in _call
    await command._invoke_with_namespace(interaction, namespace)
  File "/home/sild/.local/lib/python3.10/site-packages/discord/app_commands/commands.py", line 852, in _invoke_with_namespace
    transformed_values = await self._transform_arguments(interaction, namespace)
  File "/home/sild/.local/lib/python3.10/site-packages/discord/app_commands/commands.py", line 816, in _transform_arguments
    raise CommandSignatureMismatch(self) from None
discord.app_commands.errors.CommandSignatureMismatch: The signature for command 'ssss' is different from the one provided by Discord. This can happen because either your code is out of date or you have not synced the commands with Discord, causing the mismatch in data. It is recommended to sync the command tree to fix this issue.
[2024-01-08 18:20:38] [INFO    ] discord.client: logging in using static token
[2024-01-08 18:20:39] [INFO    ] discord.gateway: Shard ID None has connected to Gateway (Session ID: d7c8ca00a23b592f37a905c6871b9c36).
[2024-01-08 18:20:41] [INFO    ] root: Bot is ready.
[2024-01-08 18:20:43] [ERROR   ] discord.app_commands.tree: Ignoring exception in command 'ssss'
Traceback (most recent call last):
  File "/home/sild/.local/lib/python3.10/site-packages/discord/app_commands/tree.py", line 1248, in _call
    await command._invoke_with_namespace(interaction, namespace)
  File "/home/sild/.local/lib/python3.10/site-packages/discord/app_commands/commands.py", line 852, in _invoke_with_namespace
    transformed_values = await self._transform_arguments(interaction, namespace)
  File "/home/sild/.local/lib/python3.10/site-packages/discord/app_commands/commands.py", line 816, in _transform_arguments
    raise CommandSignatureMismatch(self) from None
discord.app_commands.errors.CommandSignatureMismatch: The signature for command 'ssss' is different from the one provided by Discord. This can happen because either your code is out of date or you have not synced the commands with Discord, causing the mismatch in data. It is recommended to sync the command tree to fix this issue.
[2024-01-08 18:22:54] [INFO    ] discord.client: logging in using static token
[2024-01-08 18:22:56] [INFO    ] discord.gateway: Shard ID None has connected to Gateway (Session ID: 8024412eeba4bdd22a190505d0954bdc).
[2024-01-08 18:22:58] [INFO    ] root: Bot is ready.
[2024-01-08 18:47:12] [INFO    ] discord.client: logging in using static token
[2024-01-08 18:47:13] [INFO    ] discord.gateway: Shard ID None has connected to Gateway (Session ID: ebd70a739645346d893ae7e590239ab0).
[2024-01-08 18:47:15] [INFO    ] root: Bot is ready.
[2024-01-08 18:52:14] [INFO    ] discord.client: logging in using static token
[2024-01-08 18:52:15] [INFO    ] discord.gateway: Shard ID None has connected to Gateway (Session ID: 0ffe08e48ffa06cfd1d0c5054bdb243c).
[2024-01-08 18:52:17] [INFO    ] root: Bot is ready.
[2024-01-08 18:54:23] [INFO    ] discord.client: logging in using static token
[2024-01-08 18:54:24] [INFO    ] discord.gateway: Shard ID None has connected to Gateway (Session ID: 56222590a9fccfe67ec922edfa71ba4f).
[2024-01-08 18:54:26] [INFO    ] root: Bot is ready.
[2024-01-08 18:56:49] [INFO    ] discord.client: logging in using static token
[2024-01-08 18:56:51] [INFO    ] discord.gateway: Shard ID None has connected to Gateway (Session ID: bb2d3f9d414a235b6daebfe6de8570db).
[2024-01-08 18:56:53] [INFO    ] root: Bot is ready.
[2024-01-08 18:57:00] [ERROR   ] discord.app_commands.tree: Ignoring exception in command 'register_reaction_for_tracking'
Traceback (most recent call last):
  File "/home/sild/.local/lib/python3.10/site-packages/discord/app_commands/commands.py", line 827, in _do_call
    return await self._callback(self.binding, interaction, **params)  # type: ignore
  File "/home/sild/Documents/KaoruBot/src/bot_commands.py", line 62, in add_reaction_to_tracker
    if interaction.user._permissions.administrator:
AttributeError: 'int' object has no attribute 'administrator'

The above exception was the direct cause of the following exception:

Traceback (most recent call last):
  File "/home/sild/.local/lib/python3.10/site-packages/discord/app_commands/tree.py", line 1248, in _call
    await command._invoke_with_namespace(interaction, namespace)
  File "/home/sild/.local/lib/python3.10/site-packages/discord/app_commands/commands.py", line 853, in _invoke_with_namespace
    return await self._do_call(interaction, transformed_values)
  File "/home/sild/.local/lib/python3.10/site-packages/discord/app_commands/commands.py", line 846, in _do_call
    raise CommandInvokeError(self, e) from e
discord.app_commands.errors.CommandInvokeError: Command 'register_reaction_for_tracking' raised an exception: AttributeError: 'int' object has no attribute 'administrator'
[2024-01-08 18:58:32] [INFO    ] discord.client: logging in using static token
[2024-01-08 18:58:33] [INFO    ] discord.gateway: Shard ID None has connected to Gateway (Session ID: e09aa8d87f6264fb9ea35e23704fa12b).
[2024-01-08 18:58:35] [INFO    ] root: Bot is ready.
[2024-01-08 18:58:37] [ERROR   ] discord.app_commands.tree: Ignoring exception in command 'register_reaction_for_tracking'
Traceback (most recent call last):
  File "/home/sild/.local/lib/python3.10/site-packages/discord/app_commands/commands.py", line 827, in _do_call
    return await self._callback(self.binding, interaction, **params)  # type: ignore
  File "/home/sild/Documents/KaoruBot/src/bot_commands.py", line 62, in add_reaction_to_tracker
    if interaction.user.server_permissions.administrator:
AttributeError: 'Member' object has no attribute 'server_permissions'

The above exception was the direct cause of the following exception:

Traceback (most recent call last):
  File "/home/sild/.local/lib/python3.10/site-packages/discord/app_commands/tree.py", line 1248, in _call
    await command._invoke_with_namespace(interaction, namespace)
  File "/home/sild/.local/lib/python3.10/site-packages/discord/app_commands/commands.py", line 853, in _invoke_with_namespace
    return await self._do_call(interaction, transformed_values)
  File "/home/sild/.local/lib/python3.10/site-packages/discord/app_commands/commands.py", line 846, in _do_call
    raise CommandInvokeError(self, e) from e
discord.app_commands.errors.CommandInvokeError: Command 'register_reaction_for_tracking' raised an exception: AttributeError: 'Member' object has no attribute 'server_permissions'
[2024-01-08 18:59:24] [INFO    ] discord.client: logging in using static token
[2024-01-08 18:59:25] [INFO    ] discord.gateway: Shard ID None has connected to Gateway (Session ID: 3219be118e203d81426a0c5085310780).
[2024-01-08 18:59:27] [INFO    ] root: Bot is ready.
[2024-01-08 19:00:17] [INFO    ] discord.client: logging in using static token
[2024-01-08 19:00:18] [INFO    ] discord.gateway: Shard ID None has connected to Gateway (Session ID: 228a82b98cae5a13fe753629899897a1).
[2024-01-08 19:00:20] [INFO    ] root: Bot is ready.
[2024-01-08 19:01:45] [ERROR   ] discord.app_commands.tree: Ignoring exception in command tree
Traceback (most recent call last):
  File "/home/sild/.local/lib/python3.10/site-packages/discord/app_commands/tree.py", line 1089, in wrapper
    await self._call(interaction)
  File "/home/sild/.local/lib/python3.10/site-packages/discord/app_commands/tree.py", line 1221, in _call
    command, options = self._get_app_command_options(data)
  File "/home/sild/.local/lib/python3.10/site-packages/discord/app_commands/tree.py", line 1125, in _get_app_command_options
    raise CommandNotFound(name, parents)
discord.app_commands.errors.CommandNotFound: Application command 'ssss' not found
[2024-01-08 19:11:12] [INFO    ] discord.client: logging in using static token
[2024-01-08 19:11:13] [INFO    ] discord.gateway: Shard ID None has connected to Gateway (Session ID: 6309bc9c11a135659f2e7ecdafbcf7ad).
[2024-01-08 19:11:15] [INFO    ] root: Bot is ready.
[2024-01-08 19:11:20] [INFO    ] discord.client: logging in using static token
[2024-01-08 19:11:21] [INFO    ] discord.gateway: Shard ID None has connected to Gateway (Session ID: 86b2499d8ef30620687b2aefc80f8ebd).
[2024-01-08 19:11:23] [INFO    ] root: Bot is ready.
[2024-01-08 19:11:27] [ERROR   ] discord.app_commands.tree: Ignoring exception in command 'register_reaction_for_tracking'
Traceback (most recent call last):
  File "/home/sild/.local/lib/python3.10/site-packages/discord/app_commands/commands.py", line 827, in _do_call
    return await self._callback(self.binding, interaction, **params)  # type: ignore
  File "/home/sild/Documents/KaoruBot/src/bot_commands.py", line 67, in add_reaction_to_tracker
    self.bot.database.insert_or_update(
  File "/home/sild/Documents/KaoruBot/src/database.py", line 13, in insert
    self.conn.execute(f"INSERT INTO {table_name} ({columns}) VALUES ({values})")
sqlite3.OperationalError: table reaction_tracker has no column named trached_reaction_emoji

The above exception was the direct cause of the following exception:

Traceback (most recent call last):
  File "/home/sild/.local/lib/python3.10/site-packages/discord/app_commands/tree.py", line 1248, in _call
    await command._invoke_with_namespace(interaction, namespace)
  File "/home/sild/.local/lib/python3.10/site-packages/discord/app_commands/commands.py", line 853, in _invoke_with_namespace
    return await self._do_call(interaction, transformed_values)
  File "/home/sild/.local/lib/python3.10/site-packages/discord/app_commands/commands.py", line 846, in _do_call
    raise CommandInvokeError(self, e) from e
discord.app_commands.errors.CommandInvokeError: Command 'register_reaction_for_tracking' raised an exception: OperationalError: table reaction_tracker has no column named trached_reaction_emoji
[2024-01-08 19:11:53] [INFO    ] discord.client: logging in using static token
[2024-01-08 19:11:55] [INFO    ] discord.gateway: Shard ID None has connected to Gateway (Session ID: b9c0757726b129fbfc4e3e9a94747670).
[2024-01-08 19:11:57] [INFO    ] root: Bot is ready.
[2024-01-08 19:13:35] [INFO    ] discord.client: logging in using static token
[2024-01-08 19:13:36] [INFO    ] discord.gateway: Shard ID None has connected to Gateway (Session ID: 9dc83d3741b7e2449932eec1c424e42a).
[2024-01-08 19:13:38] [INFO    ] root: Bot is ready.
[2024-01-08 19:14:31] [INFO    ] discord.client: logging in using static token
[2024-01-08 19:14:32] [INFO    ] discord.gateway: Shard ID None has connected to Gateway (Session ID: d3f87e302efc57c9d942ab920289aaed).
[2024-01-08 19:14:34] [INFO    ] root: Bot is ready.
[2024-01-08 19:15:07] [INFO    ] discord.client: logging in using static token
[2024-01-08 19:15:08] [INFO    ] discord.gateway: Shard ID None has connected to Gateway (Session ID: bc1229acd3cf71d44cc353a275654505).
[2024-01-08 19:15:10] [INFO    ] root: Bot is ready.
[2024-01-08 19:15:32] [INFO    ] discord.client: logging in using static token
[2024-01-08 19:15:33] [INFO    ] discord.gateway: Shard ID None has connected to Gateway (Session ID: 455abb0a4e1eb6bc9bda880366c01c6a).
[2024-01-08 19:15:35] [INFO    ] root: Bot is ready.
[2024-01-08 19:15:36] [ERROR   ] discord.client: Ignoring exception in on_raw_reaction_add
Traceback (most recent call last):
  File "/home/sild/.local/lib/python3.10/site-packages/discord/client.py", line 441, in _run_event
    await coro(*args, **kwargs)
  File "/home/sild/Documents/KaoruBot/src/bot_events.py", line 51, in on_raw_reaction_add
    subscribed_reactions = self.bot.database.select(
  File "/home/sild/Documents/KaoruBot/src/database.py", line 17, in select
    return self.conn.execute(f"SELECT {columns} FROM {table_name} WHERE {where}")
sqlite3.OperationalError: no such column: message_id
[2024-01-08 19:16:32] [INFO    ] discord.client: logging in using static token
[2024-01-08 19:16:34] [INFO    ] discord.gateway: Shard ID None has connected to Gateway (Session ID: d6ee34fda6e60ba3bfc5228e2a7095d5).
[2024-01-08 19:16:36] [INFO    ] root: Bot is ready.
[2024-01-08 19:16:37] [ERROR   ] discord.client: Ignoring exception in on_raw_reaction_add
Traceback (most recent call last):
  File "/home/sild/.local/lib/python3.10/site-packages/discord/client.py", line 441, in _run_event
    await coro(*args, **kwargs)
  File "/home/sild/Documents/KaoruBot/src/bot_events.py", line 51, in on_raw_reaction_add
    table_name="reaction_tracker",
  File "/home/sild/Documents/KaoruBot/src/database.py", line 17, in select
    return self.conn.execute(f"SELECT {columns} FROM {table_name} WHERE {where}")
sqlite3.OperationalError: no such column: message_id
[2024-01-08 19:16:37] [ERROR   ] discord.client: Ignoring exception in on_raw_reaction_add
Traceback (most recent call last):
  File "/home/sild/.local/lib/python3.10/site-packages/discord/client.py", line 441, in _run_event
    await coro(*args, **kwargs)
  File "/home/sild/Documents/KaoruBot/src/bot_events.py", line 50, in on_raw_reaction_add
    subscribed_reactions = self.bot.database.select(
  File "/home/sild/Documents/KaoruBot/src/database.py", line 17, in select
    return self.conn.execute(f"SELECT {columns} FROM {table_name} WHERE {where}")
sqlite3.OperationalError: no such column: message_id
[2024-01-08 19:17:19] [INFO    ] discord.client: logging in using static token
[2024-01-08 19:17:21] [INFO    ] discord.gateway: Shard ID None has connected to Gateway (Session ID: 741e1d549e84e4d75770d012509daa35).
[2024-01-08 19:17:23] [INFO    ] root: Bot is ready.
[2024-01-08 19:17:25] [ERROR   ] discord.client: Ignoring exception in on_raw_reaction_add
Traceback (most recent call last):
  File "/home/sild/.local/lib/python3.10/site-packages/discord/client.py", line 441, in _run_event
    await coro(*args, **kwargs)
  File "/home/sild/Documents/KaoruBot/src/bot_events.py", line 60, in on_raw_reaction_add
    if reaction_emoji == emoji.strip():
AttributeError: 'PartialEmoji' object has no attribute 'strip'
[2024-01-08 19:17:25] [ERROR   ] discord.client: Ignoring exception in on_raw_reaction_add
Traceback (most recent call last):
  File "/home/sild/.local/lib/python3.10/site-packages/discord/client.py", line 441, in _run_event
    await coro(*args, **kwargs)
  File "/home/sild/Documents/KaoruBot/src/bot_events.py", line 51, in on_raw_reaction_add
    table_name="reaction_tracker",
  File "/home/sild/Documents/KaoruBot/src/database.py", line 17, in select
    return self.conn.execute(f"SELECT {columns} FROM {table_name} WHERE {where}")
sqlite3.OperationalError: no such column: message_id
[2024-01-08 19:17:45] [ERROR   ] discord.client: Ignoring exception in on_raw_reaction_add
Traceback (most recent call last):
  File "/home/sild/.local/lib/python3.10/site-packages/discord/client.py", line 441, in _run_event
    await coro(*args, **kwargs)
  File "/home/sild/Documents/KaoruBot/src/bot_events.py", line 51, in on_raw_reaction_add
    table_name="reaction_tracker",
  File "/home/sild/Documents/KaoruBot/src/database.py", line 17, in select
    return self.conn.execute(f"SELECT {columns} FROM {table_name} WHERE {where}")
sqlite3.OperationalError: no such column: message_id
[2024-01-08 19:17:47] [ERROR   ] discord.client: Ignoring exception in on_raw_reaction_add
Traceback (most recent call last):
  File "/home/sild/.local/lib/python3.10/site-packages/discord/client.py", line 441, in _run_event
    await coro(*args, **kwargs)
  File "/home/sild/Documents/KaoruBot/src/bot_events.py", line 60, in on_raw_reaction_add
    if reaction_emoji == emoji.strip():
AttributeError: 'PartialEmoji' object has no attribute 'strip'
[2024-01-08 19:18:10] [INFO    ] discord.client: logging in using static token
[2024-01-08 19:18:11] [INFO    ] discord.gateway: Shard ID None has connected to Gateway (Session ID: 62197aa5cc318f0ad6883c4c650afc38).
[2024-01-08 19:18:13] [INFO    ] root: Bot is ready.
[2024-01-08 19:18:21] [ERROR   ] discord.client: Ignoring exception in on_raw_reaction_add
Traceback (most recent call last):
  File "/home/sild/.local/lib/python3.10/site-packages/discord/client.py", line 441, in _run_event
    await coro(*args, **kwargs)
  File "/home/sild/Documents/KaoruBot/src/bot_events.py", line 60, in on_raw_reaction_add
    if reaction_emoji == emoji.strip():
AttributeError: 'PartialEmoji' object has no attribute 'strip'
[2024-01-08 19:18:21] [ERROR   ] discord.client: Ignoring exception in on_raw_reaction_add
Traceback (most recent call last):
  File "/home/sild/.local/lib/python3.10/site-packages/discord/client.py", line 441, in _run_event
    await coro(*args, **kwargs)
  File "/home/sild/Documents/KaoruBot/src/bot_events.py", line 51, in on_raw_reaction_add
    table_name="reaction_tracker",
  File "/home/sild/Documents/KaoruBot/src/database.py", line 17, in select
    return self.conn.execute(f"SELECT {columns} FROM {table_name} WHERE {where}")
sqlite3.OperationalError: no such column: message_id
[2024-01-08 19:18:54] [INFO    ] discord.client: logging in using static token
[2024-01-08 19:18:55] [INFO    ] discord.gateway: Shard ID None has connected to Gateway (Session ID: 41b0481150856cea12d4b0553287c869).
[2024-01-08 19:18:57] [INFO    ] root: Bot is ready.
[2024-01-08 19:19:00] [ERROR   ] discord.client: Ignoring exception in on_raw_reaction_add
Traceback (most recent call last):
  File "/home/sild/.local/lib/python3.10/site-packages/discord/client.py", line 441, in _run_event
    await coro(*args, **kwargs)
  File "/home/sild/Documents/KaoruBot/src/bot_events.py", line 51, in on_raw_reaction_add
    table_name="reaction_tracker",
  File "/home/sild/Documents/KaoruBot/src/database.py", line 17, in select
    return self.conn.execute(f"SELECT {columns} FROM {table_name} WHERE {where}")
sqlite3.OperationalError: no such column: message_id
[2024-01-08 19:19:55] [INFO    ] discord.client: logging in using static token
[2024-01-08 19:19:56] [INFO    ] discord.gateway: Shard ID None has connected to Gateway (Session ID: e46874c29984b9faffa9269353027cba).
[2024-01-08 19:19:58] [INFO    ] root: Bot is ready.
[2024-01-08 19:20:01] [ERROR   ] discord.client: Ignoring exception in on_raw_reaction_add
Traceback (most recent call last):
  File "/home/sild/.local/lib/python3.10/site-packages/discord/client.py", line 441, in _run_event
    await coro(*args, **kwargs)
  File "/home/sild/Documents/KaoruBot/src/bot_events.py", line 51, in on_raw_reaction_add
    table_name="reaction_tracker",
  File "/home/sild/Documents/KaoruBot/src/database.py", line 17, in select
    return self.conn.execute(f"SELECT {columns} FROM {table_name} WHERE {where}")
sqlite3.OperationalError: no such column: message_id
[2024-01-08 19:20:11] [INFO    ] discord.client: logging in using static token
[2024-01-08 19:20:12] [INFO    ] discord.gateway: Shard ID None has connected to Gateway (Session ID: efc08613d390f191df37923ec2d84090).
[2024-01-08 19:20:14] [INFO    ] root: Bot is ready.
[2024-01-08 19:20:24] [ERROR   ] discord.app_commands.tree: Ignoring exception in command 'register_reaction_for_tracking'
Traceback (most recent call last):
  File "/home/sild/.local/lib/python3.10/site-packages/discord/app_commands/tree.py", line 1248, in _call
    await command._invoke_with_namespace(interaction, namespace)
  File "/home/sild/.local/lib/python3.10/site-packages/discord/app_commands/commands.py", line 852, in _invoke_with_namespace
    transformed_values = await self._transform_arguments(interaction, namespace)
  File "/home/sild/.local/lib/python3.10/site-packages/discord/app_commands/commands.py", line 816, in _transform_arguments
    raise CommandSignatureMismatch(self) from None
discord.app_commands.errors.CommandSignatureMismatch: The signature for command 'register_reaction_for_tracking' is different from the one provided by Discord. This can happen because either your code is out of date or you have not synced the commands with Discord, causing the mismatch in data. It is recommended to sync the command tree to fix this issue.
[2024-01-08 19:20:24] [ERROR   ] discord.app_commands.tree: Ignoring exception in command 'register_reaction_for_tracking'
Traceback (most recent call last):
  File "/home/sild/.local/lib/python3.10/site-packages/discord/app_commands/commands.py", line 827, in _do_call
    return await self._callback(self.binding, interaction, **params)  # type: ignore
  File "/home/sild/Documents/KaoruBot/src/bot_commands.py", line 67, in add_reaction_to_tracker
    self.bot.database.insert_or_update(
  File "/home/sild/Documents/KaoruBot/src/database.py", line 13, in insert
    self.conn.execute(f"INSERT INTO {table_name} ({columns}) VALUES ({values})")
sqlite3.OperationalError: attempt to write a readonly database

The above exception was the direct cause of the following exception:

Traceback (most recent call last):
  File "/home/sild/.local/lib/python3.10/site-packages/discord/app_commands/tree.py", line 1248, in _call
    await command._invoke_with_namespace(interaction, namespace)
  File "/home/sild/.local/lib/python3.10/site-packages/discord/app_commands/commands.py", line 853, in _invoke_with_namespace
    return await self._do_call(interaction, transformed_values)
  File "/home/sild/.local/lib/python3.10/site-packages/discord/app_commands/commands.py", line 846, in _do_call
    raise CommandInvokeError(self, e) from e
discord.app_commands.errors.CommandInvokeError: Command 'register_reaction_for_tracking' raised an exception: OperationalError: attempt to write a readonly database
[2024-01-08 19:20:45] [ERROR   ] discord.app_commands.tree: Ignoring exception in command 'register_reaction_for_tracking'
Traceback (most recent call last):
  File "/home/sild/.local/lib/python3.10/site-packages/discord/app_commands/commands.py", line 827, in _do_call
    return await self._callback(self.binding, interaction, **params)  # type: ignore
  File "/home/sild/Documents/KaoruBot/src/bot_commands.py", line 67, in add_reaction_to_tracker
    self.bot.database.insert_or_update(
  File "/home/sild/Documents/KaoruBot/src/database.py", line 13, in insert
    self.conn.execute(f"INSERT INTO {table_name} ({columns}) VALUES ({values})")
sqlite3.OperationalError: attempt to write a readonly database

The above exception was the direct cause of the following exception:

Traceback (most recent call last):
  File "/home/sild/.local/lib/python3.10/site-packages/discord/app_commands/tree.py", line 1248, in _call
    await command._invoke_with_namespace(interaction, namespace)
  File "/home/sild/.local/lib/python3.10/site-packages/discord/app_commands/commands.py", line 853, in _invoke_with_namespace
    return await self._do_call(interaction, transformed_values)
  File "/home/sild/.local/lib/python3.10/site-packages/discord/app_commands/commands.py", line 846, in _do_call
    raise CommandInvokeError(self, e) from e
discord.app_commands.errors.CommandInvokeError: Command 'register_reaction_for_tracking' raised an exception: OperationalError: attempt to write a readonly database
[2024-01-08 19:20:53] [ERROR   ] discord.client: Ignoring exception in on_raw_reaction_add
Traceback (most recent call last):
  File "/home/sild/.local/lib/python3.10/site-packages/discord/client.py", line 441, in _run_event
    await coro(*args, **kwargs)
  File "/home/sild/Documents/KaoruBot/src/bot_events.py", line 51, in on_raw_reaction_add
    table_name="reaction_tracker",
  File "/home/sild/Documents/KaoruBot/src/database.py", line 17, in select
    return self.conn.execute(f"SELECT {columns} FROM {table_name} WHERE {where}")
sqlite3.OperationalError: no such column: message_id
[2024-01-08 19:21:17] [ERROR   ] discord.client: Ignoring exception in on_raw_reaction_add
Traceback (most recent call last):
  File "/home/sild/.local/lib/python3.10/site-packages/discord/client.py", line 441, in _run_event
    await coro(*args, **kwargs)
  File "/home/sild/Documents/KaoruBot/src/bot_events.py", line 51, in on_raw_reaction_add
    table_name="reaction_tracker",
  File "/home/sild/Documents/KaoruBot/src/database.py", line 17, in select
    return self.conn.execute(f"SELECT {columns} FROM {table_name} WHERE {where}")
sqlite3.OperationalError: no such column: message_id
[2024-01-08 19:21:20] [ERROR   ] discord.client: Ignoring exception in on_raw_reaction_add
Traceback (most recent call last):
  File "/home/sild/.local/lib/python3.10/site-packages/discord/client.py", line 441, in _run_event
    await coro(*args, **kwargs)
  File "/home/sild/Documents/KaoruBot/src/bot_events.py", line 51, in on_raw_reaction_add
    table_name="reaction_tracker",
  File "/home/sild/Documents/KaoruBot/src/database.py", line 17, in select
    return self.conn.execute(f"SELECT {columns} FROM {table_name} WHERE {where}")
sqlite3.OperationalError: no such column: message_id
[2024-01-08 19:23:31] [INFO    ] discord.client: logging in using static token
[2024-01-08 19:23:32] [INFO    ] discord.gateway: Shard ID None has connected to Gateway (Session ID: 1832162a8589acd12fcedec803f078c5).
[2024-01-08 19:23:34] [INFO    ] root: Bot is ready.
[2024-01-08 19:24:24] [ERROR   ] discord.client: Ignoring exception in on_raw_reaction_add
Traceback (most recent call last):
  File "/home/sild/.local/lib/python3.10/site-packages/discord/client.py", line 441, in _run_event
    await coro(*args, **kwargs)
  File "/home/sild/Documents/KaoruBot/src/bot_events.py", line 51, in on_raw_reaction_add
    table_name="reaction_tracker",
  File "/home/sild/Documents/KaoruBot/src/database.py", line 17, in select
    return self.conn.execute(f"SELECT {columns} FROM {table_name} WHERE {where}")
sqlite3.OperationalError: no such column: message_id
[2024-01-08 19:24:36] [ERROR   ] discord.client: Ignoring exception in on_raw_reaction_add
Traceback (most recent call last):
  File "/home/sild/.local/lib/python3.10/site-packages/discord/client.py", line 441, in _run_event
    await coro(*args, **kwargs)
  File "/home/sild/Documents/KaoruBot/src/bot_events.py", line 51, in on_raw_reaction_add
    table_name="reaction_tracker",
  File "/home/sild/Documents/KaoruBot/src/database.py", line 17, in select
    return self.conn.execute(f"SELECT {columns} FROM {table_name} WHERE {where}")
sqlite3.OperationalError: no such column: message_id
[2024-01-08 19:24:40] [ERROR   ] discord.client: Ignoring exception in on_raw_reaction_add
Traceback (most recent call last):
  File "/home/sild/.local/lib/python3.10/site-packages/discord/client.py", line 441, in _run_event
    await coro(*args, **kwargs)
  File "/home/sild/Documents/KaoruBot/src/bot_events.py", line 51, in on_raw_reaction_add
    table_name="reaction_tracker",
  File "/home/sild/Documents/KaoruBot/src/database.py", line 17, in select
    return self.conn.execute(f"SELECT {columns} FROM {table_name} WHERE {where}")
sqlite3.OperationalError: no such column: message_id
[2024-01-08 19:24:53] [ERROR   ] discord.client: Ignoring exception in on_raw_reaction_add
Traceback (most recent call last):
  File "/home/sild/.local/lib/python3.10/site-packages/discord/client.py", line 441, in _run_event
    await coro(*args, **kwargs)
  File "/home/sild/Documents/KaoruBot/src/bot_events.py", line 51, in on_raw_reaction_add
    table_name="reaction_tracker",
  File "/home/sild/Documents/KaoruBot/src/database.py", line 17, in select
    return self.conn.execute(f"SELECT {columns} FROM {table_name} WHERE {where}")
sqlite3.OperationalError: no such column: message_id
[2024-01-08 19:25:07] [ERROR   ] discord.client: Ignoring exception in on_raw_reaction_add
Traceback (most recent call last):
  File "/home/sild/.local/lib/python3.10/site-packages/discord/client.py", line 441, in _run_event
    await coro(*args, **kwargs)
  File "/home/sild/Documents/KaoruBot/src/bot_events.py", line 51, in on_raw_reaction_add
    table_name="reaction_tracker",
  File "/home/sild/Documents/KaoruBot/src/database.py", line 17, in select
    return self.conn.execute(f"SELECT {columns} FROM {table_name} WHERE {where}")
sqlite3.OperationalError: no such column: message_id
[2024-01-08 19:25:10] [ERROR   ] discord.client: Ignoring exception in on_raw_reaction_add
Traceback (most recent call last):
  File "/home/sild/.local/lib/python3.10/site-packages/discord/client.py", line 441, in _run_event
    await coro(*args, **kwargs)
  File "/home/sild/Documents/KaoruBot/src/bot_events.py", line 51, in on_raw_reaction_add
    table_name="reaction_tracker",
  File "/home/sild/Documents/KaoruBot/src/database.py", line 17, in select
    return self.conn.execute(f"SELECT {columns} FROM {table_name} WHERE {where}")
sqlite3.OperationalError: no such column: message_id
[2024-01-08 19:25:24] [ERROR   ] discord.client: Ignoring exception in on_raw_reaction_add
Traceback (most recent call last):
  File "/home/sild/.local/lib/python3.10/site-packages/discord/client.py", line 441, in _run_event
    await coro(*args, **kwargs)
  File "/home/sild/Documents/KaoruBot/src/bot_events.py", line 51, in on_raw_reaction_add
    table_name="reaction_tracker",
  File "/home/sild/Documents/KaoruBot/src/database.py", line 17, in select
    return self.conn.execute(f"SELECT {columns} FROM {table_name} WHERE {where}")
sqlite3.OperationalError: no such column: message_id
[2024-01-08 19:25:44] [ERROR   ] discord.client: Ignoring exception in on_raw_reaction_add
Traceback (most recent call last):
  File "/home/sild/.local/lib/python3.10/site-packages/discord/client.py", line 441, in _run_event
    await coro(*args, **kwargs)
  File "/home/sild/Documents/KaoruBot/src/bot_events.py", line 51, in on_raw_reaction_add
    table_name="reaction_tracker",
  File "/home/sild/Documents/KaoruBot/src/database.py", line 17, in select
    return self.conn.execute(f"SELECT {columns} FROM {table_name} WHERE {where}")
sqlite3.OperationalError: no such column: message_id
[2024-01-08 19:27:39] [ERROR   ] discord.client: Ignoring exception in on_raw_reaction_add
Traceback (most recent call last):
  File "/home/sild/.local/lib/python3.10/site-packages/discord/client.py", line 441, in _run_event
    await coro(*args, **kwargs)
  File "/home/sild/Documents/KaoruBot/src/bot_events.py", line 51, in on_raw_reaction_add
    table_name="reaction_tracker",
  File "/home/sild/Documents/KaoruBot/src/database.py", line 17, in select
    return self.conn.execute(f"SELECT {columns} FROM {table_name} WHERE {where}")
sqlite3.OperationalError: no such column: message_id
[2024-01-08 19:28:58] [INFO    ] discord.client: logging in using static token
[2024-01-08 19:28:59] [INFO    ] discord.gateway: Shard ID None has connected to Gateway (Session ID: 0c9aece7a0353a0fd3bb86e6c9a41709).
[2024-01-08 19:29:01] [INFO    ] root: Bot is ready.
[2024-01-08 19:29:08] [ERROR   ] discord.client: Ignoring exception in on_raw_reaction_add
Traceback (most recent call last):
  File "/home/sild/.local/lib/python3.10/site-packages/discord/client.py", line 441, in _run_event
    await coro(*args, **kwargs)
  File "/home/sild/Documents/KaoruBot/src/bot_events.py", line 51, in on_raw_reaction_add
    table_name="reaction_tracker",
  File "/home/sild/Documents/KaoruBot/src/database.py", line 17, in select
    return self.conn.execute(f"SELECT {columns} FROM {table_name} WHERE {where}")
sqlite3.OperationalError: no such column: message_id
[2024-01-08 19:29:18] [ERROR   ] discord.client: Ignoring exception in on_raw_reaction_add
Traceback (most recent call last):
  File "/home/sild/.local/lib/python3.10/site-packages/discord/client.py", line 441, in _run_event
    await coro(*args, **kwargs)
  File "/home/sild/Documents/KaoruBot/src/bot_events.py", line 51, in on_raw_reaction_add
    table_name="reaction_tracker",
  File "/home/sild/Documents/KaoruBot/src/database.py", line 17, in select
    return self.conn.execute(f"SELECT {columns} FROM {table_name} WHERE {where}")
sqlite3.OperationalError: no such column: message_id
[2024-01-08 19:29:35] [ERROR   ] discord.client: Ignoring exception in on_raw_reaction_add
Traceback (most recent call last):
  File "/home/sild/.local/lib/python3.10/site-packages/discord/client.py", line 441, in _run_event
    await coro(*args, **kwargs)
  File "/home/sild/Documents/KaoruBot/src/bot_events.py", line 51, in on_raw_reaction_add
    table_name="reaction_tracker",
  File "/home/sild/Documents/KaoruBot/src/database.py", line 17, in select
    return self.conn.execute(f"SELECT {columns} FROM {table_name} WHERE {where}")
sqlite3.OperationalError: no such column: message_id
[2024-01-08 19:29:38] [ERROR   ] discord.client: Ignoring exception in on_raw_reaction_add
Traceback (most recent call last):
  File "/home/sild/.local/lib/python3.10/site-packages/discord/client.py", line 441, in _run_event
    await coro(*args, **kwargs)
  File "/home/sild/Documents/KaoruBot/src/bot_events.py", line 51, in on_raw_reaction_add
    table_name="reaction_tracker",
  File "/home/sild/Documents/KaoruBot/src/database.py", line 17, in select
    return self.conn.execute(f"SELECT {columns} FROM {table_name} WHERE {where}")
sqlite3.OperationalError: no such column: message_id
[2024-01-08 19:30:29] [INFO    ] discord.client: logging in using static token
[2024-01-08 19:30:31] [INFO    ] discord.gateway: Shard ID None has connected to Gateway (Session ID: 7d8312f7841904e29d611c0125ccb258).
[2024-01-08 19:30:33] [INFO    ] root: Bot is ready.
[2024-01-08 19:30:42] [ERROR   ] discord.client: Ignoring exception in on_raw_reaction_add
Traceback (most recent call last):
  File "/home/sild/.local/lib/python3.10/site-packages/discord/client.py", line 441, in _run_event
    await coro(*args, **kwargs)
  File "/home/sild/Documents/KaoruBot/src/bot_events.py", line 60, in on_raw_reaction_add
    if reaction_emoji == emoji_name.strip() & reaction_guild_id == guild_id:
TypeError: unsupported operand type(s) for &: 'str' and 'int'
[2024-01-08 19:30:42] [ERROR   ] discord.client: Ignoring exception in on_raw_reaction_add
Traceback (most recent call last):
  File "/home/sild/.local/lib/python3.10/site-packages/discord/client.py", line 441, in _run_event
    await coro(*args, **kwargs)
  File "/home/sild/Documents/KaoruBot/src/bot_events.py", line 51, in on_raw_reaction_add
    table_name="reaction_tracker",
  File "/home/sild/Documents/KaoruBot/src/database.py", line 17, in select
    return self.conn.execute(f"SELECT {columns} FROM {table_name} WHERE {where}")
sqlite3.OperationalError: no such column: message_id
[2024-01-08 19:30:43] [ERROR   ] discord.client: Ignoring exception in on_raw_reaction_add
Traceback (most recent call last):
  File "/home/sild/.local/lib/python3.10/site-packages/discord/client.py", line 441, in _run_event
    await coro(*args, **kwargs)
  File "/home/sild/Documents/KaoruBot/src/bot_events.py", line 60, in on_raw_reaction_add
    if reaction_emoji == emoji_name.strip() & reaction_guild_id == guild_id:
TypeError: unsupported operand type(s) for &: 'str' and 'int'
[2024-01-08 19:30:43] [ERROR   ] discord.client: Ignoring exception in on_raw_reaction_add
Traceback (most recent call last):
  File "/home/sild/.local/lib/python3.10/site-packages/discord/client.py", line 441, in _run_event
    await coro(*args, **kwargs)
  File "/home/sild/Documents/KaoruBot/src/bot_events.py", line 51, in on_raw_reaction_add
    table_name="reaction_tracker",
  File "/home/sild/Documents/KaoruBot/src/database.py", line 17, in select
    return self.conn.execute(f"SELECT {columns} FROM {table_name} WHERE {where}")
sqlite3.OperationalError: no such column: message_id
[2024-01-08 19:31:03] [INFO    ] discord.client: logging in using static token
[2024-01-08 19:31:04] [INFO    ] discord.gateway: Shard ID None has connected to Gateway (Session ID: 1e967f4e0c1a6d9f6c703dc242acd45c).
[2024-01-08 19:31:06] [INFO    ] root: Bot is ready.
[2024-01-08 19:31:09] [ERROR   ] discord.client: Ignoring exception in on_raw_reaction_add
Traceback (most recent call last):
  File "/home/sild/.local/lib/python3.10/site-packages/discord/client.py", line 441, in _run_event
    await coro(*args, **kwargs)
  File "/home/sild/Documents/KaoruBot/src/bot_events.py", line 51, in on_raw_reaction_add
    table_name="reaction_tracker",
  File "/home/sild/Documents/KaoruBot/src/database.py", line 17, in select
    return self.conn.execute(f"SELECT {columns} FROM {table_name} WHERE {where}")
sqlite3.OperationalError: no such column: message_id
[2024-01-08 19:31:09] [ERROR   ] discord.client: Ignoring exception in on_raw_reaction_add
Traceback (most recent call last):
  File "/home/sild/.local/lib/python3.10/site-packages/discord/client.py", line 441, in _run_event
    await coro(*args, **kwargs)
  File "/home/sild/Documents/KaoruBot/src/bot_events.py", line 60, in on_raw_reaction_add
    if reaction_emoji == emoji_name.strip() & reaction_guild_id == guild_id:
TypeError: unsupported operand type(s) for &: 'str' and 'int'
[2024-01-08 19:31:09] [ERROR   ] discord.client: Ignoring exception in on_raw_reaction_add
Traceback (most recent call last):
  File "/home/sild/.local/lib/python3.10/site-packages/discord/client.py", line 441, in _run_event
    await coro(*args, **kwargs)
  File "/home/sild/Documents/KaoruBot/src/bot_events.py", line 51, in on_raw_reaction_add
    table_name="reaction_tracker",
  File "/home/sild/Documents/KaoruBot/src/database.py", line 17, in select
    return self.conn.execute(f"SELECT {columns} FROM {table_name} WHERE {where}")
sqlite3.OperationalError: no such column: message_id
[2024-01-08 19:31:09] [ERROR   ] discord.client: Ignoring exception in on_raw_reaction_add
Traceback (most recent call last):
  File "/home/sild/.local/lib/python3.10/site-packages/discord/client.py", line 441, in _run_event
    await coro(*args, **kwargs)
  File "/home/sild/Documents/KaoruBot/src/bot_events.py", line 60, in on_raw_reaction_add
    if reaction_emoji == emoji_name.strip() & reaction_guild_id == guild_id:
TypeError: unsupported operand type(s) for &: 'str' and 'int'
[2024-01-08 19:31:20] [ERROR   ] discord.client: Ignoring exception in on_raw_reaction_add
Traceback (most recent call last):
  File "/home/sild/.local/lib/python3.10/site-packages/discord/client.py", line 441, in _run_event
    await coro(*args, **kwargs)
  File "/home/sild/Documents/KaoruBot/src/bot_events.py", line 60, in on_raw_reaction_add
    if reaction_emoji == emoji_name.strip() & reaction_guild_id == guild_id:
TypeError: unsupported operand type(s) for &: 'str' and 'int'
[2024-01-08 19:31:20] [ERROR   ] discord.client: Ignoring exception in on_raw_reaction_add
Traceback (most recent call last):
  File "/home/sild/.local/lib/python3.10/site-packages/discord/client.py", line 441, in _run_event
    await coro(*args, **kwargs)
  File "/home/sild/Documents/KaoruBot/src/bot_events.py", line 51, in on_raw_reaction_add
    table_name="reaction_tracker",
  File "/home/sild/Documents/KaoruBot/src/database.py", line 17, in select
    return self.conn.execute(f"SELECT {columns} FROM {table_name} WHERE {where}")
sqlite3.OperationalError: no such column: message_id
[2024-01-08 19:31:43] [INFO    ] discord.client: logging in using static token
[2024-01-08 19:31:44] [INFO    ] discord.gateway: Shard ID None has connected to Gateway (Session ID: c62faa8c66e8945633b81a50a6cbc9b5).
[2024-01-08 19:31:46] [INFO    ] root: Bot is ready.
[2024-01-08 19:31:48] [ERROR   ] discord.client: Ignoring exception in on_raw_reaction_add
Traceback (most recent call last):
  File "/home/sild/.local/lib/python3.10/site-packages/discord/client.py", line 441, in _run_event
    await coro(*args, **kwargs)
  File "/home/sild/Documents/KaoruBot/src/bot_events.py", line 51, in on_raw_reaction_add
    table_name="reaction_tracker",
  File "/home/sild/Documents/KaoruBot/src/database.py", line 17, in select
    return self.conn.execute(f"SELECT {columns} FROM {table_name} WHERE {where}")
sqlite3.OperationalError: no such column: message_id
[2024-01-08 19:32:14] [ERROR   ] discord.client: Ignoring exception in on_raw_reaction_add
Traceback (most recent call last):
  File "/home/sild/.local/lib/python3.10/site-packages/discord/client.py", line 441, in _run_event
    await coro(*args, **kwargs)
  File "/home/sild/Documents/KaoruBot/src/bot_events.py", line 51, in on_raw_reaction_add
    table_name="reaction_tracker",
  File "/home/sild/Documents/KaoruBot/src/database.py", line 17, in select
    return self.conn.execute(f"SELECT {columns} FROM {table_name} WHERE {where}")
sqlite3.OperationalError: no such column: message_id
[2024-01-08 19:34:31] [ERROR   ] discord.client: Ignoring exception in on_raw_reaction_add
Traceback (most recent call last):
  File "/home/sild/.local/lib/python3.10/site-packages/discord/client.py", line 441, in _run_event
    await coro(*args, **kwargs)
  File "/home/sild/Documents/KaoruBot/src/bot_events.py", line 51, in on_raw_reaction_add
    table_name="reaction_tracker",
  File "/home/sild/Documents/KaoruBot/src/database.py", line 17, in select
    return self.conn.execute(f"SELECT {columns} FROM {table_name} WHERE {where}")
sqlite3.OperationalError: no such column: message_id
[2024-01-08 19:34:38] [ERROR   ] discord.client: Ignoring exception in on_raw_reaction_add
Traceback (most recent call last):
  File "/home/sild/.local/lib/python3.10/site-packages/discord/client.py", line 441, in _run_event
    await coro(*args, **kwargs)
  File "/home/sild/Documents/KaoruBot/src/bot_events.py", line 51, in on_raw_reaction_add
    table_name="reaction_tracker",
  File "/home/sild/Documents/KaoruBot/src/database.py", line 17, in select
    return self.conn.execute(f"SELECT {columns} FROM {table_name} WHERE {where}")
sqlite3.OperationalError: no such column: message_id
[2024-01-08 19:38:24] [ERROR   ] discord.client: Ignoring exception in on_raw_reaction_add
Traceback (most recent call last):
  File "/home/sild/.local/lib/python3.10/site-packages/discord/client.py", line 441, in _run_event
    await coro(*args, **kwargs)
  File "/home/sild/Documents/KaoruBot/src/bot_events.py", line 51, in on_raw_reaction_add
    table_name="reaction_tracker",
  File "/home/sild/Documents/KaoruBot/src/database.py", line 17, in select
    return self.conn.execute(f"SELECT {columns} FROM {table_name} WHERE {where}")
sqlite3.OperationalError: no such column: message_id
[2024-01-08 19:39:36] [ERROR   ] discord.client: Ignoring exception in on_raw_reaction_add
Traceback (most recent call last):
  File "/home/sild/.local/lib/python3.10/site-packages/discord/client.py", line 441, in _run_event
    await coro(*args, **kwargs)
  File "/home/sild/Documents/KaoruBot/src/bot_events.py", line 51, in on_raw_reaction_add
    table_name="reaction_tracker",
  File "/home/sild/Documents/KaoruBot/src/database.py", line 17, in select
    return self.conn.execute(f"SELECT {columns} FROM {table_name} WHERE {where}")
sqlite3.OperationalError: no such column: message_id
[2024-01-08 19:39:46] [ERROR   ] discord.client: Ignoring exception in on_raw_reaction_add
Traceback (most recent call last):
  File "/home/sild/.local/lib/python3.10/site-packages/discord/client.py", line 441, in _run_event
    await coro(*args, **kwargs)
  File "/home/sild/Documents/KaoruBot/src/bot_events.py", line 51, in on_raw_reaction_add
    table_name="reaction_tracker",
  File "/home/sild/Documents/KaoruBot/src/database.py", line 17, in select
    return self.conn.execute(f"SELECT {columns} FROM {table_name} WHERE {where}")
sqlite3.OperationalError: no such column: message_id
[2024-01-08 19:40:28] [ERROR   ] discord.client: Ignoring exception in on_raw_reaction_add
Traceback (most recent call last):
  File "/home/sild/.local/lib/python3.10/site-packages/discord/client.py", line 441, in _run_event
    await coro(*args, **kwargs)
  File "/home/sild/Documents/KaoruBot/src/bot_events.py", line 51, in on_raw_reaction_add
    table_name="reaction_tracker",
  File "/home/sild/Documents/KaoruBot/src/database.py", line 17, in select
    return self.conn.execute(f"SELECT {columns} FROM {table_name} WHERE {where}")
sqlite3.OperationalError: no such column: message_id
[2024-01-08 19:40:31] [ERROR   ] discord.client: Ignoring exception in on_raw_reaction_add
Traceback (most recent call last):
  File "/home/sild/.local/lib/python3.10/site-packages/discord/client.py", line 441, in _run_event
    await coro(*args, **kwargs)
  File "/home/sild/Documents/KaoruBot/src/bot_events.py", line 51, in on_raw_reaction_add
    table_name="reaction_tracker",
  File "/home/sild/Documents/KaoruBot/src/database.py", line 17, in select
    return self.conn.execute(f"SELECT {columns} FROM {table_name} WHERE {where}")
sqlite3.OperationalError: no such column: message_id
[2024-01-08 19:46:23] [ERROR   ] discord.client: Ignoring exception in on_raw_reaction_add
Traceback (most recent call last):
  File "/home/sild/.local/lib/python3.10/site-packages/discord/client.py", line 441, in _run_event
    await coro(*args, **kwargs)
  File "/home/sild/Documents/KaoruBot/src/bot_events.py", line 51, in on_raw_reaction_add
    table_name="reaction_tracker",
  File "/home/sild/Documents/KaoruBot/src/database.py", line 17, in select
    return self.conn.execute(f"SELECT {columns} FROM {table_name} WHERE {where}")
sqlite3.OperationalError: no such column: message_id
[2024-01-08 19:46:27] [ERROR   ] discord.client: Ignoring exception in on_raw_reaction_add
Traceback (most recent call last):
  File "/home/sild/.local/lib/python3.10/site-packages/discord/client.py", line 441, in _run_event
    await coro(*args, **kwargs)
  File "/home/sild/Documents/KaoruBot/src/bot_events.py", line 51, in on_raw_reaction_add
    table_name="reaction_tracker",
  File "/home/sild/Documents/KaoruBot/src/database.py", line 17, in select
    return self.conn.execute(f"SELECT {columns} FROM {table_name} WHERE {where}")
sqlite3.OperationalError: no such column: message_id
[2024-01-08 19:46:32] [ERROR   ] discord.client: Ignoring exception in on_raw_reaction_add
Traceback (most recent call last):
  File "/home/sild/.local/lib/python3.10/site-packages/discord/client.py", line 441, in _run_event
    await coro(*args, **kwargs)
  File "/home/sild/Documents/KaoruBot/src/bot_events.py", line 51, in on_raw_reaction_add
    table_name="reaction_tracker",
  File "/home/sild/Documents/KaoruBot/src/database.py", line 17, in select
    return self.conn.execute(f"SELECT {columns} FROM {table_name} WHERE {where}")
sqlite3.OperationalError: no such column: message_id
[2024-01-08 19:46:34] [ERROR   ] discord.client: Ignoring exception in on_raw_reaction_add
Traceback (most recent call last):
  File "/home/sild/.local/lib/python3.10/site-packages/discord/client.py", line 441, in _run_event
    await coro(*args, **kwargs)
  File "/home/sild/Documents/KaoruBot/src/bot_events.py", line 51, in on_raw_reaction_add
    table_name="reaction_tracker",
  File "/home/sild/Documents/KaoruBot/src/database.py", line 17, in select
    return self.conn.execute(f"SELECT {columns} FROM {table_name} WHERE {where}")
sqlite3.OperationalError: no such column: message_id
[2024-01-08 19:46:37] [ERROR   ] discord.client: Ignoring exception in on_raw_reaction_add
Traceback (most recent call last):
  File "/home/sild/.local/lib/python3.10/site-packages/discord/client.py", line 441, in _run_event
    await coro(*args, **kwargs)
  File "/home/sild/Documents/KaoruBot/src/bot_events.py", line 51, in on_raw_reaction_add
    table_name="reaction_tracker",
  File "/home/sild/Documents/KaoruBot/src/database.py", line 17, in select
    return self.conn.execute(f"SELECT {columns} FROM {table_name} WHERE {where}")
sqlite3.OperationalError: no such column: message_id
[2024-01-08 19:46:41] [ERROR   ] discord.client: Ignoring exception in on_raw_reaction_add
Traceback (most recent call last):
  File "/home/sild/.local/lib/python3.10/site-packages/discord/client.py", line 441, in _run_event
    await coro(*args, **kwargs)
  File "/home/sild/Documents/KaoruBot/src/bot_events.py", line 51, in on_raw_reaction_add
    table_name="reaction_tracker",
  File "/home/sild/Documents/KaoruBot/src/database.py", line 17, in select
    return self.conn.execute(f"SELECT {columns} FROM {table_name} WHERE {where}")
sqlite3.OperationalError: no such column: message_id
[2024-01-08 19:46:43] [ERROR   ] discord.client: Ignoring exception in on_raw_reaction_add
Traceback (most recent call last):
  File "/home/sild/.local/lib/python3.10/site-packages/discord/client.py", line 441, in _run_event
    await coro(*args, **kwargs)
  File "/home/sild/Documents/KaoruBot/src/bot_events.py", line 51, in on_raw_reaction_add
    table_name="reaction_tracker",
  File "/home/sild/Documents/KaoruBot/src/database.py", line 17, in select
    return self.conn.execute(f"SELECT {columns} FROM {table_name} WHERE {where}")
sqlite3.OperationalError: no such column: message_id
[2024-01-08 19:46:48] [ERROR   ] discord.client: Ignoring exception in on_raw_reaction_add
Traceback (most recent call last):
  File "/home/sild/.local/lib/python3.10/site-packages/discord/client.py", line 441, in _run_event
    await coro(*args, **kwargs)
  File "/home/sild/Documents/KaoruBot/src/bot_events.py", line 51, in on_raw_reaction_add
    table_name="reaction_tracker",
  File "/home/sild/Documents/KaoruBot/src/database.py", line 17, in select
    return self.conn.execute(f"SELECT {columns} FROM {table_name} WHERE {where}")
sqlite3.OperationalError: no such column: message_id
[2024-01-08 19:46:52] [ERROR   ] discord.client: Ignoring exception in on_raw_reaction_add
Traceback (most recent call last):
  File "/home/sild/.local/lib/python3.10/site-packages/discord/client.py", line 441, in _run_event
    await coro(*args, **kwargs)
  File "/home/sild/Documents/KaoruBot/src/bot_events.py", line 51, in on_raw_reaction_add
    table_name="reaction_tracker",
  File "/home/sild/Documents/KaoruBot/src/database.py", line 17, in select
    return self.conn.execute(f"SELECT {columns} FROM {table_name} WHERE {where}")
sqlite3.OperationalError: no such column: message_id
[2024-01-08 19:46:53] [ERROR   ] discord.client: Ignoring exception in on_raw_reaction_add
Traceback (most recent call last):
  File "/home/sild/.local/lib/python3.10/site-packages/discord/client.py", line 441, in _run_event
    await coro(*args, **kwargs)
  File "/home/sild/Documents/KaoruBot/src/bot_events.py", line 51, in on_raw_reaction_add
    table_name="reaction_tracker",
  File "/home/sild/Documents/KaoruBot/src/database.py", line 17, in select
    return self.conn.execute(f"SELECT {columns} FROM {table_name} WHERE {where}")
sqlite3.OperationalError: no such column: message_id
[2024-01-08 19:46:56] [ERROR   ] discord.client: Ignoring exception in on_raw_reaction_add
Traceback (most recent call last):
  File "/home/sild/.local/lib/python3.10/site-packages/discord/client.py", line 441, in _run_event
    await coro(*args, **kwargs)
  File "/home/sild/Documents/KaoruBot/src/bot_events.py", line 51, in on_raw_reaction_add
    table_name="reaction_tracker",
  File "/home/sild/Documents/KaoruBot/src/database.py", line 17, in select
    return self.conn.execute(f"SELECT {columns} FROM {table_name} WHERE {where}")
sqlite3.OperationalError: no such column: message_id
[2024-01-08 19:47:09] [ERROR   ] discord.client: Ignoring exception in on_raw_reaction_add
Traceback (most recent call last):
  File "/home/sild/.local/lib/python3.10/site-packages/discord/client.py", line 441, in _run_event
    await coro(*args, **kwargs)
  File "/home/sild/Documents/KaoruBot/src/bot_events.py", line 51, in on_raw_reaction_add
    table_name="reaction_tracker",
  File "/home/sild/Documents/KaoruBot/src/database.py", line 17, in select
    return self.conn.execute(f"SELECT {columns} FROM {table_name} WHERE {where}")
sqlite3.OperationalError: no such column: message_id
[2024-01-08 19:47:11] [ERROR   ] discord.client: Ignoring exception in on_raw_reaction_add
Traceback (most recent call last):
  File "/home/sild/.local/lib/python3.10/site-packages/discord/client.py", line 441, in _run_event
    await coro(*args, **kwargs)
  File "/home/sild/Documents/KaoruBot/src/bot_events.py", line 51, in on_raw_reaction_add
    table_name="reaction_tracker",
  File "/home/sild/Documents/KaoruBot/src/database.py", line 17, in select
    return self.conn.execute(f"SELECT {columns} FROM {table_name} WHERE {where}")
sqlite3.OperationalError: no such column: message_id
[2024-01-08 19:47:12] [ERROR   ] discord.client: Ignoring exception in on_raw_reaction_add
Traceback (most recent call last):
  File "/home/sild/.local/lib/python3.10/site-packages/discord/client.py", line 441, in _run_event
    await coro(*args, **kwargs)
  File "/home/sild/Documents/KaoruBot/src/bot_events.py", line 51, in on_raw_reaction_add
    table_name="reaction_tracker",
  File "/home/sild/Documents/KaoruBot/src/database.py", line 17, in select
    return self.conn.execute(f"SELECT {columns} FROM {table_name} WHERE {where}")
sqlite3.OperationalError: no such column: message_id
[2024-01-08 19:47:17] [ERROR   ] discord.client: Ignoring exception in on_raw_reaction_add
Traceback (most recent call last):
  File "/home/sild/.local/lib/python3.10/site-packages/discord/client.py", line 441, in _run_event
    await coro(*args, **kwargs)
  File "/home/sild/Documents/KaoruBot/src/bot_events.py", line 51, in on_raw_reaction_add
    table_name="reaction_tracker",
  File "/home/sild/Documents/KaoruBot/src/database.py", line 17, in select
    return self.conn.execute(f"SELECT {columns} FROM {table_name} WHERE {where}")
sqlite3.OperationalError: no such column: message_id
[2024-01-08 19:47:18] [ERROR   ] discord.client: Ignoring exception in on_raw_reaction_add
Traceback (most recent call last):
  File "/home/sild/.local/lib/python3.10/site-packages/discord/client.py", line 441, in _run_event
    await coro(*args, **kwargs)
  File "/home/sild/Documents/KaoruBot/src/bot_events.py", line 51, in on_raw_reaction_add
    table_name="reaction_tracker",
  File "/home/sild/Documents/KaoruBot/src/database.py", line 17, in select
    return self.conn.execute(f"SELECT {columns} FROM {table_name} WHERE {where}")
sqlite3.OperationalError: no such column: message_id
[2024-01-08 19:49:30] [ERROR   ] discord.client: Ignoring exception in on_raw_reaction_add
Traceback (most recent call last):
  File "/home/sild/.local/lib/python3.10/site-packages/discord/client.py", line 441, in _run_event
    await coro(*args, **kwargs)
  File "/home/sild/Documents/KaoruBot/src/bot_events.py", line 51, in on_raw_reaction_add
    table_name="reaction_tracker",
  File "/home/sild/Documents/KaoruBot/src/database.py", line 17, in select
    return self.conn.execute(f"SELECT {columns} FROM {table_name} WHERE {where}")
sqlite3.OperationalError: no such column: message_id
[2024-01-08 19:50:41] [ERROR   ] discord.client: Ignoring exception in on_raw_reaction_add
Traceback (most recent call last):
  File "/home/sild/.local/lib/python3.10/site-packages/discord/client.py", line 441, in _run_event
    await coro(*args, **kwargs)
  File "/home/sild/Documents/KaoruBot/src/bot_events.py", line 51, in on_raw_reaction_add
    table_name="reaction_tracker",
  File "/home/sild/Documents/KaoruBot/src/database.py", line 17, in select
    return self.conn.execute(f"SELECT {columns} FROM {table_name} WHERE {where}")
sqlite3.OperationalError: no such column: message_id
[2024-01-08 19:51:56] [ERROR   ] discord.client: Ignoring exception in on_raw_reaction_add
Traceback (most recent call last):
  File "/home/sild/.local/lib/python3.10/site-packages/discord/client.py", line 441, in _run_event
    await coro(*args, **kwargs)
  File "/home/sild/Documents/KaoruBot/src/bot_events.py", line 51, in on_raw_reaction_add
    table_name="reaction_tracker",
  File "/home/sild/Documents/KaoruBot/src/database.py", line 17, in select
    return self.conn.execute(f"SELECT {columns} FROM {table_name} WHERE {where}")
sqlite3.OperationalError: no such column: message_id
[2024-01-08 19:51:59] [INFO    ] discord.client: logging in using static token
[2024-01-08 19:52:02] [INFO    ] discord.gateway: Shard ID None has connected to Gateway (Session ID: 53165ba1cd4371e94dd83d7bc56ab4ed).
[2024-01-08 19:52:04] [INFO    ] root: Bot is ready.
[2024-01-08 19:53:58] [ERROR   ] discord.client: Ignoring exception in on_raw_reaction_add
Traceback (most recent call last):
  File "/home/sild/.local/lib/python3.10/site-packages/discord/client.py", line 441, in _run_event
    await coro(*args, **kwargs)
  File "/home/sild/Documents/KaoruBot/src/bot_events.py", line 51, in on_raw_reaction_add
    table_name="reaction_tracker",
  File "/home/sild/Documents/KaoruBot/src/database.py", line 17, in select
    return self.conn.execute(f"SELECT {columns} FROM {table_name} WHERE {where}")
sqlite3.OperationalError: no such column: message_id
[2024-01-08 19:54:00] [ERROR   ] discord.app_commands.tree: Ignoring exception in command tree
Traceback (most recent call last):
  File "/home/sild/.local/lib/python3.10/site-packages/discord/app_commands/tree.py", line 1089, in wrapper
    await self._call(interaction)
  File "/home/sild/.local/lib/python3.10/site-packages/discord/app_commands/tree.py", line 1221, in _call
    command, options = self._get_app_command_options(data)
  File "/home/sild/.local/lib/python3.10/site-packages/discord/app_commands/tree.py", line 1125, in _get_app_command_options
    raise CommandNotFound(name, parents)
discord.app_commands.errors.CommandNotFound: Application command 'selfmute' not found
[2024-01-08 19:54:01] [ERROR   ] discord.app_commands.tree: Ignoring exception in command 'selfmute'
Traceback (most recent call last):
  File "/home/sild/.local/lib/python3.10/site-packages/discord/app_commands/commands.py", line 827, in _do_call
    return await self._callback(self.binding, interaction, **params)  # type: ignore
  File "/home/sild/Documents/KaoruBot/src/bot_commands.py", line 42, in selfmute
    await interaction.user.add_roles(muted_role)
  File "/home/sild/.local/lib/python3.10/site-packages/discord/member.py", line 1051, in add_roles
    await req(guild_id, user_id, role.id, reason=reason)
  File "/home/sild/.local/lib/python3.10/site-packages/discord/http.py", line 739, in request
    raise Forbidden(response, data)
discord.errors.Forbidden: 403 Forbidden (error code: 50013): Missing Permissions

The above exception was the direct cause of the following exception:

Traceback (most recent call last):
  File "/home/sild/.local/lib/python3.10/site-packages/discord/app_commands/tree.py", line 1248, in _call
    await command._invoke_with_namespace(interaction, namespace)
  File "/home/sild/.local/lib/python3.10/site-packages/discord/app_commands/commands.py", line 853, in _invoke_with_namespace
    return await self._do_call(interaction, transformed_values)
  File "/home/sild/.local/lib/python3.10/site-packages/discord/app_commands/commands.py", line 846, in _do_call
    raise CommandInvokeError(self, e) from e
discord.app_commands.errors.CommandInvokeError: Command 'selfmute' raised an exception: Forbidden: 403 Forbidden (error code: 50013): Missing Permissions
[2024-01-08 19:57:17] [ERROR   ] discord.app_commands.tree: Ignoring exception in command tree
Traceback (most recent call last):
  File "/home/sild/.local/lib/python3.10/site-packages/discord/app_commands/tree.py", line 1089, in wrapper
    await self._call(interaction)
  File "/home/sild/.local/lib/python3.10/site-packages/discord/app_commands/tree.py", line 1221, in _call
    command, options = self._get_app_command_options(data)
  File "/home/sild/.local/lib/python3.10/site-packages/discord/app_commands/tree.py", line 1125, in _get_app_command_options
    raise CommandNotFound(name, parents)
discord.app_commands.errors.CommandNotFound: Application command 'selfmute' not found
[2024-01-08 19:57:18] [ERROR   ] discord.app_commands.tree: Ignoring exception in command 'selfmute'
Traceback (most recent call last):
  File "/home/sild/.local/lib/python3.10/site-packages/discord/app_commands/commands.py", line 827, in _do_call
    return await self._callback(self.binding, interaction, **params)  # type: ignore
  File "/home/sild/Documents/KaoruBot/src/bot_commands.py", line 57, in selfmute
    await interaction.response.send_message(content=f"You are unmuted.", ephemeral=False)
  File "/home/sild/.local/lib/python3.10/site-packages/discord/interactions.py", line 774, in send_message
    raise InteractionResponded(self._parent)
discord.errors.InteractionResponded: This interaction has already been responded to before

The above exception was the direct cause of the following exception:

Traceback (most recent call last):
  File "/home/sild/.local/lib/python3.10/site-packages/discord/app_commands/tree.py", line 1248, in _call
    await command._invoke_with_namespace(interaction, namespace)
  File "/home/sild/.local/lib/python3.10/site-packages/discord/app_commands/commands.py", line 853, in _invoke_with_namespace
    return await self._do_call(interaction, transformed_values)
  File "/home/sild/.local/lib/python3.10/site-packages/discord/app_commands/commands.py", line 846, in _do_call
    raise CommandInvokeError(self, e) from e
discord.app_commands.errors.CommandInvokeError: Command 'selfmute' raised an exception: InteractionResponded: This interaction has already been responded to before
[2024-01-08 19:57:48] [INFO    ] discord.client: logging in using static token
[2024-01-08 19:57:49] [INFO    ] discord.gateway: Shard ID None has connected to Gateway (Session ID: a421f67e8cc3de846cd172d3b53047f9).
[2024-01-08 19:57:51] [INFO    ] root: Bot is ready.
[2024-01-08 19:58:07] [ERROR   ] discord.app_commands.tree: Ignoring exception in command tree
Traceback (most recent call last):
  File "/home/sild/.local/lib/python3.10/site-packages/discord/app_commands/tree.py", line 1089, in wrapper
    await self._call(interaction)
  File "/home/sild/.local/lib/python3.10/site-packages/discord/app_commands/tree.py", line 1221, in _call
    command, options = self._get_app_command_options(data)
  File "/home/sild/.local/lib/python3.10/site-packages/discord/app_commands/tree.py", line 1125, in _get_app_command_options
    raise CommandNotFound(name, parents)
discord.app_commands.errors.CommandNotFound: Application command 'selfmute' not found
[2024-01-08 19:58:07] [ERROR   ] discord.app_commands.tree: Ignoring exception in command 'selfmute'
Traceback (most recent call last):
  File "/home/sild/.local/lib/python3.10/site-packages/discord/app_commands/commands.py", line 827, in _do_call
    return await self._callback(self.binding, interaction, **params)  # type: ignore
  File "/home/sild/Documents/KaoruBot/src/bot_commands.py", line 43, in selfmute
    self.bot.database.insert_or_update(
  File "/home/sild/Documents/KaoruBot/src/database.py", line 13, in insert
    self.conn.execute(f"INSERT INTO {table_name} ({columns}) VALUES ({values})")
sqlite3.IntegrityError: UNIQUE constraint failed: muted_users.user_id

The above exception was the direct cause of the following exception:

Traceback (most recent call last):
  File "/home/sild/.local/lib/python3.10/site-packages/discord/app_commands/tree.py", line 1248, in _call
    await command._invoke_with_namespace(interaction, namespace)
  File "/home/sild/.local/lib/python3.10/site-packages/discord/app_commands/commands.py", line 853, in _invoke_with_namespace
    return await self._do_call(interaction, transformed_values)
  File "/home/sild/.local/lib/python3.10/site-packages/discord/app_commands/commands.py", line 846, in _do_call
    raise CommandInvokeError(self, e) from e
discord.app_commands.errors.CommandInvokeError: Command 'selfmute' raised an exception: IntegrityError: UNIQUE constraint failed: muted_users.user_id
[2024-01-08 19:58:59] [ERROR   ] discord.client: Ignoring exception in on_raw_reaction_add
Traceback (most recent call last):
  File "/home/sild/.local/lib/python3.10/site-packages/discord/client.py", line 441, in _run_event
    await coro(*args, **kwargs)
  File "/home/sild/Documents/KaoruBot/src/bot_events.py", line 51, in on_raw_reaction_add
    table_name="reaction_tracker",
  File "/home/sild/Documents/KaoruBot/src/database.py", line 17, in select
    return self.conn.execute(f"SELECT {columns} FROM {table_name} WHERE {where}")
sqlite3.OperationalError: no such column: message_id
[2024-01-08 19:59:05] [ERROR   ] discord.client: Ignoring exception in on_raw_reaction_add
Traceback (most recent call last):
  File "/home/sild/.local/lib/python3.10/site-packages/discord/client.py", line 441, in _run_event
    await coro(*args, **kwargs)
  File "/home/sild/Documents/KaoruBot/src/bot_events.py", line 51, in on_raw_reaction_add
    table_name="reaction_tracker",
  File "/home/sild/Documents/KaoruBot/src/database.py", line 17, in select
    return self.conn.execute(f"SELECT {columns} FROM {table_name} WHERE {where}")
sqlite3.OperationalError: no such column: message_id
[2024-01-08 19:59:13] [INFO    ] discord.client: logging in using static token
[2024-01-08 19:59:14] [INFO    ] discord.gateway: Shard ID None has connected to Gateway (Session ID: dfa4b74d48e934f03c9af0928870b341).
[2024-01-08 19:59:16] [INFO    ] root: Bot is ready.
[2024-01-08 20:00:13] [ERROR   ] discord.app_commands.tree: Ignoring exception in command tree
Traceback (most recent call last):
  File "/home/sild/.local/lib/python3.10/site-packages/discord/app_commands/tree.py", line 1089, in wrapper
    await self._call(interaction)
  File "/home/sild/.local/lib/python3.10/site-packages/discord/app_commands/tree.py", line 1221, in _call
    command, options = self._get_app_command_options(data)
  File "/home/sild/.local/lib/python3.10/site-packages/discord/app_commands/tree.py", line 1125, in _get_app_command_options
    raise CommandNotFound(name, parents)
discord.app_commands.errors.CommandNotFound: Application command 'selfmute' not found
[2024-01-08 20:00:13] [ERROR   ] discord.app_commands.tree: Ignoring exception in command 'selfmute'
Traceback (most recent call last):
  File "/home/sild/.local/lib/python3.10/site-packages/discord/app_commands/commands.py", line 827, in _do_call
    return await self._callback(self.binding, interaction, **params)  # type: ignore
  File "/home/sild/Documents/KaoruBot/src/bot_commands.py", line 43, in selfmute
    self.bot.database.insert_or_update(
  File "/home/sild/Documents/KaoruBot/src/database.py", line 13, in insert
    self.conn.execute(f"INSERT INTO {table_name} ({columns}) VALUES ({values})")
sqlite3.IntegrityError: UNIQUE constraint failed: muted_users.user_id

The above exception was the direct cause of the following exception:

Traceback (most recent call last):
  File "/home/sild/.local/lib/python3.10/site-packages/discord/app_commands/tree.py", line 1248, in _call
    await command._invoke_with_namespace(interaction, namespace)
  File "/home/sild/.local/lib/python3.10/site-packages/discord/app_commands/commands.py", line 853, in _invoke_with_namespace
    return await self._do_call(interaction, transformed_values)
  File "/home/sild/.local/lib/python3.10/site-packages/discord/app_commands/commands.py", line 846, in _do_call
    raise CommandInvokeError(self, e) from e
discord.app_commands.errors.CommandInvokeError: Command 'selfmute' raised an exception: IntegrityError: UNIQUE constraint failed: muted_users.user_id
[2024-01-08 20:01:14] [ERROR   ] discord.client: Ignoring exception in on_raw_reaction_add
Traceback (most recent call last):
  File "/home/sild/.local/lib/python3.10/site-packages/discord/client.py", line 441, in _run_event
    await coro(*args, **kwargs)
  File "/home/sild/Documents/KaoruBot/src/bot_events.py", line 51, in on_raw_reaction_add
    table_name="reaction_tracker",
  File "/home/sild/Documents/KaoruBot/src/database.py", line 17, in select
    return self.conn.execute(f"SELECT {columns} FROM {table_name} WHERE {where}")
sqlite3.OperationalError: no such column: message_id
[2024-01-08 20:01:42] [ERROR   ] discord.client: Ignoring exception in on_raw_reaction_add
Traceback (most recent call last):
  File "/home/sild/.local/lib/python3.10/site-packages/discord/client.py", line 441, in _run_event
    await coro(*args, **kwargs)
  File "/home/sild/Documents/KaoruBot/src/bot_events.py", line 51, in on_raw_reaction_add
    table_name="reaction_tracker",
  File "/home/sild/Documents/KaoruBot/src/database.py", line 17, in select
    return self.conn.execute(f"SELECT {columns} FROM {table_name} WHERE {where}")
sqlite3.OperationalError: no such column: message_id
[2024-01-08 20:01:54] [ERROR   ] discord.client: Ignoring exception in on_raw_reaction_add
Traceback (most recent call last):
  File "/home/sild/.local/lib/python3.10/site-packages/discord/client.py", line 441, in _run_event
    await coro(*args, **kwargs)
  File "/home/sild/Documents/KaoruBot/src/bot_events.py", line 51, in on_raw_reaction_add
    table_name="reaction_tracker",
  File "/home/sild/Documents/KaoruBot/src/database.py", line 17, in select
    return self.conn.execute(f"SELECT {columns} FROM {table_name} WHERE {where}")
sqlite3.OperationalError: no such column: message_id
[2024-01-08 20:02:13] [INFO    ] discord.client: logging in using static token
[2024-01-08 20:02:15] [INFO    ] discord.gateway: Shard ID None has connected to Gateway (Session ID: 26e215cc046b4b3dfa5979fbebcf786f).
[2024-01-08 20:02:17] [ERROR   ] discord.app_commands.tree: Ignoring exception in command tree
Traceback (most recent call last):
  File "/home/sild/.local/lib/python3.10/site-packages/discord/app_commands/tree.py", line 1089, in wrapper
    await self._call(interaction)
  File "/home/sild/.local/lib/python3.10/site-packages/discord/app_commands/tree.py", line 1221, in _call
    command, options = self._get_app_command_options(data)
  File "/home/sild/.local/lib/python3.10/site-packages/discord/app_commands/tree.py", line 1125, in _get_app_command_options
    raise CommandNotFound(name, parents)
discord.app_commands.errors.CommandNotFound: Application command 'selfmute' not found
[2024-01-08 20:02:17] [INFO    ] root: Bot is ready.
[2024-01-08 20:02:17] [ERROR   ] discord.app_commands.tree: Ignoring exception in command 'selfmute'
Traceback (most recent call last):
  File "/home/sild/.local/lib/python3.10/site-packages/discord/app_commands/commands.py", line 827, in _do_call
    return await self._callback(self.binding, interaction, **params)  # type: ignore
  File "/home/sild/Documents/KaoruBot/src/bot_commands.py", line 44, in selfmute
    self.bot.database.insert_or_update(
  File "/home/sild/Documents/KaoruBot/src/database.py", line 13, in insert
    self.conn.execute(f"INSERT INTO {table_name} ({columns}) VALUES ({values})")
sqlite3.IntegrityError: UNIQUE constraint failed: muted_users.user_id

The above exception was the direct cause of the following exception:

Traceback (most recent call last):
  File "/home/sild/.local/lib/python3.10/site-packages/discord/app_commands/tree.py", line 1248, in _call
    await command._invoke_with_namespace(interaction, namespace)
  File "/home/sild/.local/lib/python3.10/site-packages/discord/app_commands/commands.py", line 853, in _invoke_with_namespace
    return await self._do_call(interaction, transformed_values)
  File "/home/sild/.local/lib/python3.10/site-packages/discord/app_commands/commands.py", line 846, in _do_call
    raise CommandInvokeError(self, e) from e
discord.app_commands.errors.CommandInvokeError: Command 'selfmute' raised an exception: IntegrityError: UNIQUE constraint failed: muted_users.user_id
[2024-01-08 20:03:10] [ERROR   ] discord.client: Ignoring exception in on_raw_reaction_add
Traceback (most recent call last):
  File "/home/sild/.local/lib/python3.10/site-packages/discord/client.py", line 441, in _run_event
    await coro(*args, **kwargs)
  File "/home/sild/Documents/KaoruBot/src/bot_events.py", line 51, in on_raw_reaction_add
    table_name="reaction_tracker",
  File "/home/sild/Documents/KaoruBot/src/database.py", line 17, in select
    return self.conn.execute(f"SELECT {columns} FROM {table_name} WHERE {where}")
sqlite3.OperationalError: no such column: message_id
[2024-01-08 20:03:51] [ERROR   ] discord.client: Ignoring exception in on_raw_reaction_add
Traceback (most recent call last):
  File "/home/sild/.local/lib/python3.10/site-packages/discord/client.py", line 441, in _run_event
    await coro(*args, **kwargs)
  File "/home/sild/Documents/KaoruBot/src/bot_events.py", line 51, in on_raw_reaction_add
    table_name="reaction_tracker",
  File "/home/sild/Documents/KaoruBot/src/database.py", line 17, in select
    return self.conn.execute(f"SELECT {columns} FROM {table_name} WHERE {where}")
sqlite3.OperationalError: no such column: message_id
[2024-01-08 20:05:38] [ERROR   ] discord.client: Ignoring exception in on_raw_reaction_add
Traceback (most recent call last):
  File "/home/sild/.local/lib/python3.10/site-packages/discord/client.py", line 441, in _run_event
    await coro(*args, **kwargs)
  File "/home/sild/Documents/KaoruBot/src/bot_events.py", line 51, in on_raw_reaction_add
    table_name="reaction_tracker",
  File "/home/sild/Documents/KaoruBot/src/database.py", line 17, in select
    return self.conn.execute(f"SELECT {columns} FROM {table_name} WHERE {where}")
sqlite3.OperationalError: no such column: message_id
[2024-01-08 20:07:15] [INFO    ] discord.gateway: Shard ID None has successfully RESUMED session 455abb0a4e1eb6bc9bda880366c01c6a.
[2024-01-08 20:07:16] [INFO    ] discord.client: logging in using static token
[2024-01-08 20:07:18] [INFO    ] discord.gateway: Shard ID None has connected to Gateway (Session ID: e694c196d10406478e13e9f39e962cab).
[2024-01-08 20:07:20] [INFO    ] root: Bot is ready.
[2024-01-08 20:07:37] [ERROR   ] discord.app_commands.tree: Ignoring exception in command tree
Traceback (most recent call last):
  File "/home/sild/.local/lib/python3.10/site-packages/discord/app_commands/tree.py", line 1089, in wrapper
    await self._call(interaction)
  File "/home/sild/.local/lib/python3.10/site-packages/discord/app_commands/tree.py", line 1221, in _call
    command, options = self._get_app_command_options(data)
  File "/home/sild/.local/lib/python3.10/site-packages/discord/app_commands/tree.py", line 1125, in _get_app_command_options
    raise CommandNotFound(name, parents)
discord.app_commands.errors.CommandNotFound: Application command 'selfmute' not found
[2024-01-08 20:07:37] [ERROR   ] discord.app_commands.tree: Ignoring exception in command 'selfmute'
Traceback (most recent call last):
  File "/home/sild/.local/lib/python3.10/site-packages/discord/app_commands/commands.py", line 827, in _do_call
    return await self._callback(self.binding, interaction, **params)  # type: ignore
  File "/home/sild/Documents/KaoruBot/src/bot_commands.py", line 44, in selfmute
    self.bot.database.insert_or_update(
  File "/home/sild/Documents/KaoruBot/src/database.py", line 13, in insert
    self.conn.execute(f"INSERT INTO OR IGNORE {table_name} ({columns}) VALUES ({values})")
sqlite3.OperationalError: near "OR": syntax error

The above exception was the direct cause of the following exception:

Traceback (most recent call last):
  File "/home/sild/.local/lib/python3.10/site-packages/discord/app_commands/tree.py", line 1248, in _call
    await command._invoke_with_namespace(interaction, namespace)
  File "/home/sild/.local/lib/python3.10/site-packages/discord/app_commands/commands.py", line 853, in _invoke_with_namespace
    return await self._do_call(interaction, transformed_values)
  File "/home/sild/.local/lib/python3.10/site-packages/discord/app_commands/commands.py", line 846, in _do_call
    raise CommandInvokeError(self, e) from e
discord.app_commands.errors.CommandInvokeError: Command 'selfmute' raised an exception: OperationalError: near "OR": syntax error
[2024-01-08 20:08:10] [INFO    ] discord.client: logging in using static token
[2024-01-08 20:08:11] [INFO    ] discord.gateway: Shard ID None has connected to Gateway (Session ID: d17583a671459f3c861df5ada8ecda74).
[2024-01-08 20:08:13] [INFO    ] root: Bot is ready.
[2024-01-08 20:08:18] [ERROR   ] discord.app_commands.tree: Ignoring exception in command tree
Traceback (most recent call last):
  File "/home/sild/.local/lib/python3.10/site-packages/discord/app_commands/tree.py", line 1089, in wrapper
    await self._call(interaction)
  File "/home/sild/.local/lib/python3.10/site-packages/discord/app_commands/tree.py", line 1221, in _call
    command, options = self._get_app_command_options(data)
  File "/home/sild/.local/lib/python3.10/site-packages/discord/app_commands/tree.py", line 1125, in _get_app_command_options
    raise CommandNotFound(name, parents)
discord.app_commands.errors.CommandNotFound: Application command 'selfmute' not found
[2024-01-08 20:08:31] [ERROR   ] discord.app_commands.tree: Ignoring exception in command 'selfmute'
Traceback (most recent call last):
  File "/home/sild/.local/lib/python3.10/site-packages/discord/app_commands/commands.py", line 827, in _do_call
    return await self._callback(self.binding, interaction, **params)  # type: ignore
  File "/home/sild/Documents/KaoruBot/src/bot_commands.py", line 58, in selfmute
    await interaction.response.send_message(content=f"You are unmuted.", ephemeral=False)
  File "/home/sild/.local/lib/python3.10/site-packages/discord/interactions.py", line 774, in send_message
    raise InteractionResponded(self._parent)
discord.errors.InteractionResponded: This interaction has already been responded to before

The above exception was the direct cause of the following exception:

Traceback (most recent call last):
  File "/home/sild/.local/lib/python3.10/site-packages/discord/app_commands/tree.py", line 1248, in _call
    await command._invoke_with_namespace(interaction, namespace)
  File "/home/sild/.local/lib/python3.10/site-packages/discord/app_commands/commands.py", line 853, in _invoke_with_namespace
    return await self._do_call(interaction, transformed_values)
  File "/home/sild/.local/lib/python3.10/site-packages/discord/app_commands/commands.py", line 846, in _do_call
    raise CommandInvokeError(self, e) from e
discord.app_commands.errors.CommandInvokeError: Command 'selfmute' raised an exception: InteractionResponded: This interaction has already been responded to before
[2024-01-08 20:09:39] [INFO    ] discord.client: logging in using static token
[2024-01-08 20:09:40] [INFO    ] discord.gateway: Shard ID None has connected to Gateway (Session ID: 4a4adf8293b7310704354dcc758cb071).
[2024-01-08 20:09:42] [INFO    ] root: Bot is ready.
[2024-01-08 20:09:44] [ERROR   ] discord.app_commands.tree: Ignoring exception in command tree
Traceback (most recent call last):
  File "/home/sild/.local/lib/python3.10/site-packages/discord/app_commands/tree.py", line 1089, in wrapper
    await self._call(interaction)
  File "/home/sild/.local/lib/python3.10/site-packages/discord/app_commands/tree.py", line 1221, in _call
    command, options = self._get_app_command_options(data)
  File "/home/sild/.local/lib/python3.10/site-packages/discord/app_commands/tree.py", line 1125, in _get_app_command_options
    raise CommandNotFound(name, parents)
discord.app_commands.errors.CommandNotFound: Application command 'selfmute' not found
[2024-01-08 20:10:08] [ERROR   ] discord.client: Ignoring exception in on_raw_reaction_add
Traceback (most recent call last):
  File "/home/sild/.local/lib/python3.10/site-packages/discord/client.py", line 441, in _run_event
    await coro(*args, **kwargs)
  File "/home/sild/Documents/KaoruBot/src/bot_events.py", line 51, in on_raw_reaction_add
    table_name="reaction_tracker",
  File "/home/sild/Documents/KaoruBot/src/database.py", line 17, in select
    return self.conn.execute(f"SELECT {columns} FROM {table_name} WHERE {where}")
sqlite3.OperationalError: no such column: message_id
[2024-01-08 20:10:52] [ERROR   ] discord.app_commands.tree: Ignoring exception in command tree
Traceback (most recent call last):
  File "/home/sild/.local/lib/python3.10/site-packages/discord/app_commands/tree.py", line 1089, in wrapper
    await self._call(interaction)
  File "/home/sild/.local/lib/python3.10/site-packages/discord/app_commands/tree.py", line 1221, in _call
    command, options = self._get_app_command_options(data)
  File "/home/sild/.local/lib/python3.10/site-packages/discord/app_commands/tree.py", line 1125, in _get_app_command_options
    raise CommandNotFound(name, parents)
discord.app_commands.errors.CommandNotFound: Application command 'selfmute' not found
[2024-01-08 20:11:44] [ERROR   ] discord.app_commands.tree: Ignoring exception in command tree
Traceback (most recent call last):
  File "/home/sild/.local/lib/python3.10/site-packages/discord/app_commands/tree.py", line 1089, in wrapper
    await self._call(interaction)
  File "/home/sild/.local/lib/python3.10/site-packages/discord/app_commands/tree.py", line 1221, in _call
    command, options = self._get_app_command_options(data)
  File "/home/sild/.local/lib/python3.10/site-packages/discord/app_commands/tree.py", line 1125, in _get_app_command_options
    raise CommandNotFound(name, parents)
discord.app_commands.errors.CommandNotFound: Application command 'selfmute' not found
[2024-01-08 20:12:28] [ERROR   ] discord.client: Ignoring exception in on_raw_reaction_add
Traceback (most recent call last):
  File "/home/sild/.local/lib/python3.10/site-packages/discord/client.py", line 441, in _run_event
    await coro(*args, **kwargs)
  File "/home/sild/Documents/KaoruBot/src/bot_events.py", line 51, in on_raw_reaction_add
    table_name="reaction_tracker",
  File "/home/sild/Documents/KaoruBot/src/database.py", line 17, in select
    return self.conn.execute(f"SELECT {columns} FROM {table_name} WHERE {where}")
sqlite3.OperationalError: no such column: message_id
[2024-01-08 20:15:17] [ERROR   ] discord.client: Ignoring exception in on_raw_reaction_add
Traceback (most recent call last):
  File "/home/sild/.local/lib/python3.10/site-packages/discord/client.py", line 441, in _run_event
    await coro(*args, **kwargs)
  File "/home/sild/Documents/KaoruBot/src/bot_events.py", line 51, in on_raw_reaction_add
    table_name="reaction_tracker",
  File "/home/sild/Documents/KaoruBot/src/database.py", line 17, in select
    return self.conn.execute(f"SELECT {columns} FROM {table_name} WHERE {where}")
sqlite3.OperationalError: no such column: message_id
[2024-01-08 20:15:36] [ERROR   ] discord.client: Ignoring exception in on_raw_reaction_add
Traceback (most recent call last):
  File "/home/sild/.local/lib/python3.10/site-packages/discord/client.py", line 441, in _run_event
    await coro(*args, **kwargs)
  File "/home/sild/Documents/KaoruBot/src/bot_events.py", line 51, in on_raw_reaction_add
    table_name="reaction_tracker",
  File "/home/sild/Documents/KaoruBot/src/database.py", line 17, in select
    return self.conn.execute(f"SELECT {columns} FROM {table_name} WHERE {where}")
sqlite3.OperationalError: no such column: message_id
[2024-01-08 20:16:49] [ERROR   ] discord.client: Ignoring exception in on_raw_reaction_add
Traceback (most recent call last):
  File "/home/sild/.local/lib/python3.10/site-packages/discord/client.py", line 441, in _run_event
    await coro(*args, **kwargs)
  File "/home/sild/Documents/KaoruBot/src/bot_events.py", line 51, in on_raw_reaction_add
    table_name="reaction_tracker",
  File "/home/sild/Documents/KaoruBot/src/database.py", line 17, in select
    return self.conn.execute(f"SELECT {columns} FROM {table_name} WHERE {where}")
sqlite3.OperationalError: no such column: message_id
[2024-01-08 20:19:22] [ERROR   ] discord.client: Ignoring exception in on_raw_reaction_add
Traceback (most recent call last):
  File "/home/sild/.local/lib/python3.10/site-packages/discord/client.py", line 441, in _run_event
    await coro(*args, **kwargs)
  File "/home/sild/Documents/KaoruBot/src/bot_events.py", line 51, in on_raw_reaction_add
    table_name="reaction_tracker",
  File "/home/sild/Documents/KaoruBot/src/database.py", line 17, in select
    return self.conn.execute(f"SELECT {columns} FROM {table_name} WHERE {where}")
sqlite3.OperationalError: no such column: message_id
[2024-01-08 20:24:32] [ERROR   ] discord.client: Attempting a reconnect in 1.44s
Traceback (most recent call last):
  File "/home/sild/.local/lib/python3.10/site-packages/discord/client.py", line 659, in connect
    await self.ws.poll_event()
  File "/home/sild/.local/lib/python3.10/site-packages/discord/gateway.py", line 646, in poll_event
    raise ConnectionClosed(self.socket, shard_id=self.shard_id, code=code) from None
discord.errors.ConnectionClosed: Shard ID None WebSocket closed with 1000
[2024-01-08 20:24:34] [INFO    ] discord.gateway: Shard ID None has successfully RESUMED session 455abb0a4e1eb6bc9bda880366c01c6a.
[2024-01-08 20:25:55] [ERROR   ] discord.client: Ignoring exception in on_raw_reaction_add
Traceback (most recent call last):
  File "/home/sild/.local/lib/python3.10/site-packages/discord/client.py", line 441, in _run_event
    await coro(*args, **kwargs)
  File "/home/sild/Documents/KaoruBot/src/bot_events.py", line 51, in on_raw_reaction_add
    table_name="reaction_tracker",
  File "/home/sild/Documents/KaoruBot/src/database.py", line 17, in select
    return self.conn.execute(f"SELECT {columns} FROM {table_name} WHERE {where}")
sqlite3.OperationalError: no such column: message_id
[2024-01-08 20:27:01] [ERROR   ] discord.client: Ignoring exception in on_raw_reaction_add
Traceback (most recent call last):
  File "/home/sild/.local/lib/python3.10/site-packages/discord/client.py", line 441, in _run_event
    await coro(*args, **kwargs)
  File "/home/sild/Documents/KaoruBot/src/bot_events.py", line 51, in on_raw_reaction_add
    table_name="reaction_tracker",
  File "/home/sild/Documents/KaoruBot/src/database.py", line 17, in select
    return self.conn.execute(f"SELECT {columns} FROM {table_name} WHERE {where}")
sqlite3.OperationalError: no such column: message_id
[2024-01-08 20:28:33] [ERROR   ] discord.client: Ignoring exception in on_raw_reaction_add
Traceback (most recent call last):
  File "/home/sild/.local/lib/python3.10/site-packages/discord/client.py", line 441, in _run_event
    await coro(*args, **kwargs)
  File "/home/sild/Documents/KaoruBot/src/bot_events.py", line 51, in on_raw_reaction_add
    table_name="reaction_tracker",
  File "/home/sild/Documents/KaoruBot/src/database.py", line 17, in select
    return self.conn.execute(f"SELECT {columns} FROM {table_name} WHERE {where}")
sqlite3.OperationalError: no such column: message_id
[2024-01-08 20:28:44] [ERROR   ] discord.client: Ignoring exception in on_raw_reaction_add
Traceback (most recent call last):
  File "/home/sild/.local/lib/python3.10/site-packages/discord/client.py", line 441, in _run_event
    await coro(*args, **kwargs)
  File "/home/sild/Documents/KaoruBot/src/bot_events.py", line 51, in on_raw_reaction_add
    table_name="reaction_tracker",
  File "/home/sild/Documents/KaoruBot/src/database.py", line 17, in select
    return self.conn.execute(f"SELECT {columns} FROM {table_name} WHERE {where}")
sqlite3.OperationalError: no such column: message_id
[2024-01-08 20:29:07] [ERROR   ] discord.client: Ignoring exception in on_raw_reaction_add
Traceback (most recent call last):
  File "/home/sild/.local/lib/python3.10/site-packages/discord/client.py", line 441, in _run_event
    await coro(*args, **kwargs)
  File "/home/sild/Documents/KaoruBot/src/bot_events.py", line 51, in on_raw_reaction_add
    table_name="reaction_tracker",
  File "/home/sild/Documents/KaoruBot/src/database.py", line 17, in select
    return self.conn.execute(f"SELECT {columns} FROM {table_name} WHERE {where}")
sqlite3.OperationalError: no such column: message_id
[2024-01-08 20:30:32] [ERROR   ] discord.client: Ignoring exception in on_raw_reaction_add
Traceback (most recent call last):
  File "/home/sild/.local/lib/python3.10/site-packages/discord/client.py", line 441, in _run_event
    await coro(*args, **kwargs)
  File "/home/sild/Documents/KaoruBot/src/bot_events.py", line 51, in on_raw_reaction_add
    table_name="reaction_tracker",
  File "/home/sild/Documents/KaoruBot/src/database.py", line 17, in select
    return self.conn.execute(f"SELECT {columns} FROM {table_name} WHERE {where}")
sqlite3.OperationalError: no such column: message_id
[2024-01-08 20:33:34] [ERROR   ] discord.client: Ignoring exception in on_raw_reaction_add
Traceback (most recent call last):
  File "/home/sild/.local/lib/python3.10/site-packages/discord/client.py", line 441, in _run_event
    await coro(*args, **kwargs)
  File "/home/sild/Documents/KaoruBot/src/bot_events.py", line 51, in on_raw_reaction_add
    table_name="reaction_tracker",
  File "/home/sild/Documents/KaoruBot/src/database.py", line 17, in select
    return self.conn.execute(f"SELECT {columns} FROM {table_name} WHERE {where}")
sqlite3.OperationalError: no such column: message_id
[2024-01-08 20:33:42] [ERROR   ] discord.client: Ignoring exception in on_raw_reaction_add
Traceback (most recent call last):
  File "/home/sild/.local/lib/python3.10/site-packages/discord/client.py", line 441, in _run_event
    await coro(*args, **kwargs)
  File "/home/sild/Documents/KaoruBot/src/bot_events.py", line 51, in on_raw_reaction_add
    table_name="reaction_tracker",
  File "/home/sild/Documents/KaoruBot/src/database.py", line 17, in select
    return self.conn.execute(f"SELECT {columns} FROM {table_name} WHERE {where}")
sqlite3.OperationalError: no such column: message_id
[2024-01-08 20:34:28] [ERROR   ] discord.client: Ignoring exception in on_raw_reaction_add
Traceback (most recent call last):
  File "/home/sild/.local/lib/python3.10/site-packages/discord/client.py", line 441, in _run_event
    await coro(*args, **kwargs)
  File "/home/sild/Documents/KaoruBot/src/bot_events.py", line 51, in on_raw_reaction_add
    table_name="reaction_tracker",
  File "/home/sild/Documents/KaoruBot/src/database.py", line 17, in select
    return self.conn.execute(f"SELECT {columns} FROM {table_name} WHERE {where}")
sqlite3.OperationalError: no such column: message_id
[2024-01-08 20:36:43] [ERROR   ] discord.client: Ignoring exception in on_raw_reaction_add
Traceback (most recent call last):
  File "/home/sild/.local/lib/python3.10/site-packages/discord/client.py", line 441, in _run_event
    await coro(*args, **kwargs)
  File "/home/sild/Documents/KaoruBot/src/bot_events.py", line 51, in on_raw_reaction_add
    table_name="reaction_tracker",
  File "/home/sild/Documents/KaoruBot/src/database.py", line 17, in select
    return self.conn.execute(f"SELECT {columns} FROM {table_name} WHERE {where}")
sqlite3.OperationalError: no such column: message_id
[2024-01-08 20:39:01] [ERROR   ] discord.client: Ignoring exception in on_raw_reaction_add
Traceback (most recent call last):
  File "/home/sild/.local/lib/python3.10/site-packages/discord/client.py", line 441, in _run_event
    await coro(*args, **kwargs)
  File "/home/sild/Documents/KaoruBot/src/bot_events.py", line 51, in on_raw_reaction_add
    table_name="reaction_tracker",
  File "/home/sild/Documents/KaoruBot/src/database.py", line 17, in select
    return self.conn.execute(f"SELECT {columns} FROM {table_name} WHERE {where}")
sqlite3.OperationalError: no such column: message_id
[2024-01-08 20:39:03] [ERROR   ] discord.client: Ignoring exception in on_raw_reaction_add
Traceback (most recent call last):
  File "/home/sild/.local/lib/python3.10/site-packages/discord/client.py", line 441, in _run_event
    await coro(*args, **kwargs)
  File "/home/sild/Documents/KaoruBot/src/bot_events.py", line 51, in on_raw_reaction_add
    table_name="reaction_tracker",
  File "/home/sild/Documents/KaoruBot/src/database.py", line 17, in select
    return self.conn.execute(f"SELECT {columns} FROM {table_name} WHERE {where}")
sqlite3.OperationalError: no such column: message_id
[2024-01-08 20:39:04] [ERROR   ] discord.client: Ignoring exception in on_raw_reaction_add
Traceback (most recent call last):
  File "/home/sild/.local/lib/python3.10/site-packages/discord/client.py", line 441, in _run_event
    await coro(*args, **kwargs)
  File "/home/sild/Documents/KaoruBot/src/bot_events.py", line 51, in on_raw_reaction_add
    table_name="reaction_tracker",
  File "/home/sild/Documents/KaoruBot/src/database.py", line 17, in select
    return self.conn.execute(f"SELECT {columns} FROM {table_name} WHERE {where}")
sqlite3.OperationalError: no such column: message_id
[2024-01-08 20:51:18] [ERROR   ] discord.client: Ignoring exception in on_raw_reaction_add
Traceback (most recent call last):
  File "/home/sild/.local/lib/python3.10/site-packages/discord/client.py", line 441, in _run_event
    await coro(*args, **kwargs)
  File "/home/sild/Documents/KaoruBot/src/bot_events.py", line 51, in on_raw_reaction_add
    table_name="reaction_tracker",
  File "/home/sild/Documents/KaoruBot/src/database.py", line 17, in select
    return self.conn.execute(f"SELECT {columns} FROM {table_name} WHERE {where}")
sqlite3.OperationalError: no such column: message_id
[2024-01-08 20:51:24] [ERROR   ] discord.client: Ignoring exception in on_raw_reaction_add
Traceback (most recent call last):
  File "/home/sild/.local/lib/python3.10/site-packages/discord/client.py", line 441, in _run_event
    await coro(*args, **kwargs)
  File "/home/sild/Documents/KaoruBot/src/bot_events.py", line 51, in on_raw_reaction_add
    table_name="reaction_tracker",
  File "/home/sild/Documents/KaoruBot/src/database.py", line 17, in select
    return self.conn.execute(f"SELECT {columns} FROM {table_name} WHERE {where}")
sqlite3.OperationalError: no such column: message_id
[2024-01-08 20:52:06] [ERROR   ] discord.client: Attempting a reconnect in 1.54s
Traceback (most recent call last):
  File "/home/sild/.local/lib/python3.10/site-packages/discord/client.py", line 659, in connect
    await self.ws.poll_event()
  File "/home/sild/.local/lib/python3.10/site-packages/discord/gateway.py", line 646, in poll_event
    raise ConnectionClosed(self.socket, shard_id=self.shard_id, code=code) from None
discord.errors.ConnectionClosed: Shard ID None WebSocket closed with 1000
[2024-01-08 20:52:08] [INFO    ] discord.gateway: Shard ID None has successfully RESUMED session 4a4adf8293b7310704354dcc758cb071.
[2024-01-08 20:52:20] [ERROR   ] discord.client: Ignoring exception in on_raw_reaction_add
Traceback (most recent call last):
  File "/home/sild/.local/lib/python3.10/site-packages/discord/client.py", line 441, in _run_event
    await coro(*args, **kwargs)
  File "/home/sild/Documents/KaoruBot/src/bot_events.py", line 51, in on_raw_reaction_add
    table_name="reaction_tracker",
  File "/home/sild/Documents/KaoruBot/src/database.py", line 17, in select
    return self.conn.execute(f"SELECT {columns} FROM {table_name} WHERE {where}")
sqlite3.OperationalError: no such column: message_id
[2024-01-08 20:52:22] [ERROR   ] discord.client: Ignoring exception in on_raw_reaction_add
Traceback (most recent call last):
  File "/home/sild/.local/lib/python3.10/site-packages/discord/client.py", line 441, in _run_event
    await coro(*args, **kwargs)
  File "/home/sild/Documents/KaoruBot/src/bot_events.py", line 51, in on_raw_reaction_add
    table_name="reaction_tracker",
  File "/home/sild/Documents/KaoruBot/src/database.py", line 17, in select
    return self.conn.execute(f"SELECT {columns} FROM {table_name} WHERE {where}")
sqlite3.OperationalError: no such column: message_id
[2024-01-08 20:55:04] [ERROR   ] discord.client: Ignoring exception in on_raw_reaction_add
Traceback (most recent call last):
  File "/home/sild/.local/lib/python3.10/site-packages/discord/client.py", line 441, in _run_event
    await coro(*args, **kwargs)
  File "/home/sild/Documents/KaoruBot/src/bot_events.py", line 51, in on_raw_reaction_add
    table_name="reaction_tracker",
  File "/home/sild/Documents/KaoruBot/src/database.py", line 17, in select
    return self.conn.execute(f"SELECT {columns} FROM {table_name} WHERE {where}")
sqlite3.OperationalError: no such column: message_id
[2024-01-08 21:08:21] [ERROR   ] discord.client: Ignoring exception in on_raw_reaction_add
Traceback (most recent call last):
  File "/home/sild/.local/lib/python3.10/site-packages/discord/client.py", line 441, in _run_event
    await coro(*args, **kwargs)
  File "/home/sild/Documents/KaoruBot/src/bot_events.py", line 51, in on_raw_reaction_add
    table_name="reaction_tracker",
  File "/home/sild/Documents/KaoruBot/src/database.py", line 17, in select
    return self.conn.execute(f"SELECT {columns} FROM {table_name} WHERE {where}")
sqlite3.OperationalError: no such column: message_id
[2024-01-08 21:10:36] [ERROR   ] discord.client: Ignoring exception in on_raw_reaction_add
Traceback (most recent call last):
  File "/home/sild/.local/lib/python3.10/site-packages/discord/client.py", line 441, in _run_event
    await coro(*args, **kwargs)
  File "/home/sild/Documents/KaoruBot/src/bot_events.py", line 51, in on_raw_reaction_add
    table_name="reaction_tracker",
  File "/home/sild/Documents/KaoruBot/src/database.py", line 17, in select
    return self.conn.execute(f"SELECT {columns} FROM {table_name} WHERE {where}")
sqlite3.OperationalError: no such column: message_id
[2024-01-08 21:11:45] [ERROR   ] discord.app_commands.tree: Ignoring exception in command 'selfmute'
Traceback (most recent call last):
  File "/home/sild/.local/lib/python3.10/site-packages/discord/app_commands/commands.py", line 827, in _do_call
    return await self._callback(self.binding, interaction, **params)  # type: ignore
  File "/home/sild/Documents/KaoruBot/src/bot_commands.py", line 58, in selfmute
    await interaction.followup.send(content=f"{interaction.user.mention} You are unmuted.", ephemeral=False)
  File "/home/sild/.local/lib/python3.10/site-packages/discord/webhook/async_.py", line 1805, in send
    data = await adapter.execute_webhook(
  File "/home/sild/.local/lib/python3.10/site-packages/discord/webhook/async_.py", line 221, in request
    raise HTTPException(response, data)
discord.errors.HTTPException: 401 Unauthorized (error code: 50027): Invalid Webhook Token

The above exception was the direct cause of the following exception:

Traceback (most recent call last):
  File "/home/sild/.local/lib/python3.10/site-packages/discord/app_commands/tree.py", line 1248, in _call
    await command._invoke_with_namespace(interaction, namespace)
  File "/home/sild/.local/lib/python3.10/site-packages/discord/app_commands/commands.py", line 853, in _invoke_with_namespace
    return await self._do_call(interaction, transformed_values)
  File "/home/sild/.local/lib/python3.10/site-packages/discord/app_commands/commands.py", line 846, in _do_call
    raise CommandInvokeError(self, e) from e
discord.app_commands.errors.CommandInvokeError: Command 'selfmute' raised an exception: HTTPException: 401 Unauthorized (error code: 50027): Invalid Webhook Token
[2024-01-08 21:14:31] [ERROR   ] discord.client: Ignoring exception in on_raw_reaction_add
Traceback (most recent call last):
  File "/home/sild/.local/lib/python3.10/site-packages/discord/client.py", line 441, in _run_event
    await coro(*args, **kwargs)
  File "/home/sild/Documents/KaoruBot/src/bot_events.py", line 51, in on_raw_reaction_add
    table_name="reaction_tracker",
  File "/home/sild/Documents/KaoruBot/src/database.py", line 17, in select
    return self.conn.execute(f"SELECT {columns} FROM {table_name} WHERE {where}")
sqlite3.OperationalError: no such column: message_id
[2024-01-08 21:15:25] [ERROR   ] discord.client: Ignoring exception in on_raw_reaction_add
Traceback (most recent call last):
  File "/home/sild/.local/lib/python3.10/site-packages/discord/client.py", line 441, in _run_event
    await coro(*args, **kwargs)
  File "/home/sild/Documents/KaoruBot/src/bot_events.py", line 51, in on_raw_reaction_add
    table_name="reaction_tracker",
  File "/home/sild/Documents/KaoruBot/src/database.py", line 17, in select
    return self.conn.execute(f"SELECT {columns} FROM {table_name} WHERE {where}")
sqlite3.OperationalError: no such column: message_id
[2024-01-08 21:15:54] [ERROR   ] discord.client: Ignoring exception in on_raw_reaction_add
Traceback (most recent call last):
  File "/home/sild/.local/lib/python3.10/site-packages/discord/client.py", line 441, in _run_event
    await coro(*args, **kwargs)
  File "/home/sild/Documents/KaoruBot/src/bot_events.py", line 51, in on_raw_reaction_add
    table_name="reaction_tracker",
  File "/home/sild/Documents/KaoruBot/src/database.py", line 17, in select
    return self.conn.execute(f"SELECT {columns} FROM {table_name} WHERE {where}")
sqlite3.OperationalError: no such column: message_id
[2024-01-08 21:23:02] [INFO    ] discord.gateway: Shard ID None has successfully RESUMED session 455abb0a4e1eb6bc9bda880366c01c6a.
[2024-01-08 21:28:03] [ERROR   ] discord.client: Ignoring exception in on_raw_reaction_add
Traceback (most recent call last):
  File "/home/sild/.local/lib/python3.10/site-packages/discord/client.py", line 441, in _run_event
    await coro(*args, **kwargs)
  File "/home/sild/Documents/KaoruBot/src/bot_events.py", line 51, in on_raw_reaction_add
    table_name="reaction_tracker",
  File "/home/sild/Documents/KaoruBot/src/database.py", line 17, in select
    return self.conn.execute(f"SELECT {columns} FROM {table_name} WHERE {where}")
sqlite3.OperationalError: no such column: message_id
[2024-01-08 21:28:18] [ERROR   ] discord.client: Ignoring exception in on_raw_reaction_add
Traceback (most recent call last):
  File "/home/sild/.local/lib/python3.10/site-packages/discord/client.py", line 441, in _run_event
    await coro(*args, **kwargs)
  File "/home/sild/Documents/KaoruBot/src/bot_events.py", line 51, in on_raw_reaction_add
    table_name="reaction_tracker",
  File "/home/sild/Documents/KaoruBot/src/database.py", line 17, in select
    return self.conn.execute(f"SELECT {columns} FROM {table_name} WHERE {where}")
sqlite3.OperationalError: no such column: message_id
[2024-01-08 21:28:23] [ERROR   ] discord.client: Ignoring exception in on_raw_reaction_add
Traceback (most recent call last):
  File "/home/sild/.local/lib/python3.10/site-packages/discord/client.py", line 441, in _run_event
    await coro(*args, **kwargs)
  File "/home/sild/Documents/KaoruBot/src/bot_events.py", line 51, in on_raw_reaction_add
    table_name="reaction_tracker",
  File "/home/sild/Documents/KaoruBot/src/database.py", line 17, in select
    return self.conn.execute(f"SELECT {columns} FROM {table_name} WHERE {where}")
sqlite3.OperationalError: no such column: message_id
[2024-01-08 21:32:27] [ERROR   ] discord.client: Ignoring exception in on_raw_reaction_add
Traceback (most recent call last):
  File "/home/sild/.local/lib/python3.10/site-packages/discord/client.py", line 441, in _run_event
    await coro(*args, **kwargs)
  File "/home/sild/Documents/KaoruBot/src/bot_events.py", line 51, in on_raw_reaction_add
    table_name="reaction_tracker",
  File "/home/sild/Documents/KaoruBot/src/database.py", line 17, in select
    return self.conn.execute(f"SELECT {columns} FROM {table_name} WHERE {where}")
sqlite3.OperationalError: no such column: message_id
[2024-01-08 21:32:33] [ERROR   ] discord.client: Ignoring exception in on_raw_reaction_add
Traceback (most recent call last):
  File "/home/sild/.local/lib/python3.10/site-packages/discord/client.py", line 441, in _run_event
    await coro(*args, **kwargs)
  File "/home/sild/Documents/KaoruBot/src/bot_events.py", line 51, in on_raw_reaction_add
    table_name="reaction_tracker",
  File "/home/sild/Documents/KaoruBot/src/database.py", line 17, in select
    return self.conn.execute(f"SELECT {columns} FROM {table_name} WHERE {where}")
sqlite3.OperationalError: no such column: message_id
[2024-01-08 21:34:55] [INFO    ] discord.gateway: Shard ID None has successfully RESUMED session 4a4adf8293b7310704354dcc758cb071.
[2024-01-08 21:36:06] [ERROR   ] discord.client: Ignoring exception in on_raw_reaction_add
Traceback (most recent call last):
  File "/home/sild/.local/lib/python3.10/site-packages/discord/client.py", line 441, in _run_event
    await coro(*args, **kwargs)
  File "/home/sild/Documents/KaoruBot/src/bot_events.py", line 51, in on_raw_reaction_add
    table_name="reaction_tracker",
  File "/home/sild/Documents/KaoruBot/src/database.py", line 17, in select
    return self.conn.execute(f"SELECT {columns} FROM {table_name} WHERE {where}")
sqlite3.OperationalError: no such column: message_id
[2024-01-08 21:37:18] [ERROR   ] discord.client: Ignoring exception in on_raw_reaction_add
Traceback (most recent call last):
  File "/home/sild/.local/lib/python3.10/site-packages/discord/client.py", line 441, in _run_event
    await coro(*args, **kwargs)
  File "/home/sild/Documents/KaoruBot/src/bot_events.py", line 51, in on_raw_reaction_add
    table_name="reaction_tracker",
  File "/home/sild/Documents/KaoruBot/src/database.py", line 17, in select
    return self.conn.execute(f"SELECT {columns} FROM {table_name} WHERE {where}")
sqlite3.OperationalError: no such column: message_id
[2024-01-08 21:37:19] [ERROR   ] discord.client: Ignoring exception in on_raw_reaction_add
Traceback (most recent call last):
  File "/home/sild/.local/lib/python3.10/site-packages/discord/client.py", line 441, in _run_event
    await coro(*args, **kwargs)
  File "/home/sild/Documents/KaoruBot/src/bot_events.py", line 51, in on_raw_reaction_add
    table_name="reaction_tracker",
  File "/home/sild/Documents/KaoruBot/src/database.py", line 17, in select
    return self.conn.execute(f"SELECT {columns} FROM {table_name} WHERE {where}")
sqlite3.OperationalError: no such column: message_id
[2024-01-08 21:37:20] [WARNING ] discord.http: We are being rate limited. GET https://discord.com/api/v10/channels/1193603529298940107/messages/1194016954818760825 responded with 429. Retrying in 0.30 seconds.
[2024-01-08 21:37:20] [ERROR   ] discord.client: Ignoring exception in on_raw_reaction_add
Traceback (most recent call last):
  File "/home/sild/.local/lib/python3.10/site-packages/discord/client.py", line 441, in _run_event
    await coro(*args, **kwargs)
  File "/home/sild/Documents/KaoruBot/src/bot_events.py", line 51, in on_raw_reaction_add
    table_name="reaction_tracker",
  File "/home/sild/Documents/KaoruBot/src/database.py", line 17, in select
    return self.conn.execute(f"SELECT {columns} FROM {table_name} WHERE {where}")
sqlite3.OperationalError: no such column: message_id
[2024-01-08 21:37:25] [ERROR   ] discord.client: Ignoring exception in on_raw_reaction_add
Traceback (most recent call last):
  File "/home/sild/.local/lib/python3.10/site-packages/discord/client.py", line 441, in _run_event
    await coro(*args, **kwargs)
  File "/home/sild/Documents/KaoruBot/src/bot_events.py", line 51, in on_raw_reaction_add
    table_name="reaction_tracker",
  File "/home/sild/Documents/KaoruBot/src/database.py", line 17, in select
    return self.conn.execute(f"SELECT {columns} FROM {table_name} WHERE {where}")
sqlite3.OperationalError: no such column: message_id
[2024-01-08 21:44:32] [ERROR   ] discord.client: Ignoring exception in on_raw_reaction_add
Traceback (most recent call last):
  File "/home/sild/.local/lib/python3.10/site-packages/discord/client.py", line 441, in _run_event
    await coro(*args, **kwargs)
  File "/home/sild/Documents/KaoruBot/src/bot_events.py", line 51, in on_raw_reaction_add
    table_name="reaction_tracker",
  File "/home/sild/Documents/KaoruBot/src/database.py", line 17, in select
    return self.conn.execute(f"SELECT {columns} FROM {table_name} WHERE {where}")
sqlite3.OperationalError: no such column: message_id
[2024-01-08 21:49:57] [ERROR   ] discord.client: Ignoring exception in on_raw_reaction_add
Traceback (most recent call last):
  File "/home/sild/.local/lib/python3.10/site-packages/discord/client.py", line 441, in _run_event
    await coro(*args, **kwargs)
  File "/home/sild/Documents/KaoruBot/src/bot_events.py", line 51, in on_raw_reaction_add
    table_name="reaction_tracker",
  File "/home/sild/Documents/KaoruBot/src/database.py", line 17, in select
    return self.conn.execute(f"SELECT {columns} FROM {table_name} WHERE {where}")
sqlite3.OperationalError: no such column: message_id
[2024-01-08 21:50:11] [ERROR   ] discord.client: Ignoring exception in on_raw_reaction_add
Traceback (most recent call last):
  File "/home/sild/.local/lib/python3.10/site-packages/discord/client.py", line 441, in _run_event
    await coro(*args, **kwargs)
  File "/home/sild/Documents/KaoruBot/src/bot_events.py", line 51, in on_raw_reaction_add
    table_name="reaction_tracker",
  File "/home/sild/Documents/KaoruBot/src/database.py", line 17, in select
    return self.conn.execute(f"SELECT {columns} FROM {table_name} WHERE {where}")
sqlite3.OperationalError: no such column: message_id
[2024-01-08 21:50:19] [ERROR   ] discord.client: Ignoring exception in on_raw_reaction_add
Traceback (most recent call last):
  File "/home/sild/.local/lib/python3.10/site-packages/discord/client.py", line 441, in _run_event
    await coro(*args, **kwargs)
  File "/home/sild/Documents/KaoruBot/src/bot_events.py", line 51, in on_raw_reaction_add
    table_name="reaction_tracker",
  File "/home/sild/Documents/KaoruBot/src/database.py", line 17, in select
    return self.conn.execute(f"SELECT {columns} FROM {table_name} WHERE {where}")
sqlite3.OperationalError: no such column: message_id
[2024-01-08 21:50:39] [ERROR   ] discord.client: Ignoring exception in on_raw_reaction_add
Traceback (most recent call last):
  File "/home/sild/.local/lib/python3.10/site-packages/discord/client.py", line 441, in _run_event
    await coro(*args, **kwargs)
  File "/home/sild/Documents/KaoruBot/src/bot_events.py", line 51, in on_raw_reaction_add
    table_name="reaction_tracker",
  File "/home/sild/Documents/KaoruBot/src/database.py", line 17, in select
    return self.conn.execute(f"SELECT {columns} FROM {table_name} WHERE {where}")
sqlite3.OperationalError: no such column: message_id
[2024-01-08 21:50:42] [ERROR   ] discord.client: Ignoring exception in on_raw_reaction_add
Traceback (most recent call last):
  File "/home/sild/.local/lib/python3.10/site-packages/discord/client.py", line 441, in _run_event
    await coro(*args, **kwargs)
  File "/home/sild/Documents/KaoruBot/src/bot_events.py", line 51, in on_raw_reaction_add
    table_name="reaction_tracker",
  File "/home/sild/Documents/KaoruBot/src/database.py", line 17, in select
    return self.conn.execute(f"SELECT {columns} FROM {table_name} WHERE {where}")
sqlite3.OperationalError: no such column: message_id
[2024-01-08 21:50:51] [ERROR   ] discord.client: Ignoring exception in on_raw_reaction_add
Traceback (most recent call last):
  File "/home/sild/.local/lib/python3.10/site-packages/discord/client.py", line 441, in _run_event
    await coro(*args, **kwargs)
  File "/home/sild/Documents/KaoruBot/src/bot_events.py", line 51, in on_raw_reaction_add
    table_name="reaction_tracker",
  File "/home/sild/Documents/KaoruBot/src/database.py", line 17, in select
    return self.conn.execute(f"SELECT {columns} FROM {table_name} WHERE {where}")
sqlite3.OperationalError: no such column: message_id
[2024-01-08 21:51:15] [ERROR   ] discord.client: Ignoring exception in on_raw_reaction_add
Traceback (most recent call last):
  File "/home/sild/.local/lib/python3.10/site-packages/discord/client.py", line 441, in _run_event
    await coro(*args, **kwargs)
  File "/home/sild/Documents/KaoruBot/src/bot_events.py", line 51, in on_raw_reaction_add
    table_name="reaction_tracker",
  File "/home/sild/Documents/KaoruBot/src/database.py", line 17, in select
    return self.conn.execute(f"SELECT {columns} FROM {table_name} WHERE {where}")
sqlite3.OperationalError: no such column: message_id
[2024-01-08 21:51:42] [ERROR   ] discord.client: Ignoring exception in on_raw_reaction_add
Traceback (most recent call last):
  File "/home/sild/.local/lib/python3.10/site-packages/discord/client.py", line 441, in _run_event
    await coro(*args, **kwargs)
  File "/home/sild/Documents/KaoruBot/src/bot_events.py", line 51, in on_raw_reaction_add
    table_name="reaction_tracker",
  File "/home/sild/Documents/KaoruBot/src/database.py", line 17, in select
    return self.conn.execute(f"SELECT {columns} FROM {table_name} WHERE {where}")
sqlite3.OperationalError: no such column: message_id
[2024-01-08 21:52:53] [ERROR   ] discord.client: Ignoring exception in on_raw_reaction_add
Traceback (most recent call last):
  File "/home/sild/.local/lib/python3.10/site-packages/discord/client.py", line 441, in _run_event
    await coro(*args, **kwargs)
  File "/home/sild/Documents/KaoruBot/src/bot_events.py", line 51, in on_raw_reaction_add
    table_name="reaction_tracker",
  File "/home/sild/Documents/KaoruBot/src/database.py", line 17, in select
    return self.conn.execute(f"SELECT {columns} FROM {table_name} WHERE {where}")
sqlite3.OperationalError: no such column: message_id
[2024-01-08 21:59:16] [ERROR   ] discord.client: Ignoring exception in on_raw_reaction_add
Traceback (most recent call last):
  File "/home/sild/.local/lib/python3.10/site-packages/discord/client.py", line 441, in _run_event
    await coro(*args, **kwargs)
  File "/home/sild/Documents/KaoruBot/src/bot_events.py", line 51, in on_raw_reaction_add
    table_name="reaction_tracker",
  File "/home/sild/Documents/KaoruBot/src/database.py", line 17, in select
    return self.conn.execute(f"SELECT {columns} FROM {table_name} WHERE {where}")
sqlite3.OperationalError: no such column: message_id
[2024-01-08 21:59:20] [ERROR   ] discord.client: Ignoring exception in on_raw_reaction_add
Traceback (most recent call last):
  File "/home/sild/.local/lib/python3.10/site-packages/discord/client.py", line 441, in _run_event
    await coro(*args, **kwargs)
  File "/home/sild/Documents/KaoruBot/src/bot_events.py", line 51, in on_raw_reaction_add
    table_name="reaction_tracker",
  File "/home/sild/Documents/KaoruBot/src/database.py", line 17, in select
    return self.conn.execute(f"SELECT {columns} FROM {table_name} WHERE {where}")
sqlite3.OperationalError: no such column: message_id
[2024-01-08 21:59:41] [ERROR   ] discord.client: Ignoring exception in on_raw_reaction_add
Traceback (most recent call last):
  File "/home/sild/.local/lib/python3.10/site-packages/discord/client.py", line 441, in _run_event
    await coro(*args, **kwargs)
  File "/home/sild/Documents/KaoruBot/src/bot_events.py", line 51, in on_raw_reaction_add
    table_name="reaction_tracker",
  File "/home/sild/Documents/KaoruBot/src/database.py", line 17, in select
    return self.conn.execute(f"SELECT {columns} FROM {table_name} WHERE {where}")
sqlite3.OperationalError: no such column: message_id
[2024-01-08 22:03:30] [ERROR   ] discord.client: Ignoring exception in on_raw_reaction_add
Traceback (most recent call last):
  File "/home/sild/.local/lib/python3.10/site-packages/discord/client.py", line 441, in _run_event
    await coro(*args, **kwargs)
  File "/home/sild/Documents/KaoruBot/src/bot_events.py", line 51, in on_raw_reaction_add
    table_name="reaction_tracker",
  File "/home/sild/Documents/KaoruBot/src/database.py", line 17, in select
    return self.conn.execute(f"SELECT {columns} FROM {table_name} WHERE {where}")
sqlite3.OperationalError: no such column: message_id
[2024-01-08 22:03:46] [ERROR   ] discord.client: Ignoring exception in on_raw_reaction_add
Traceback (most recent call last):
  File "/home/sild/.local/lib/python3.10/site-packages/discord/client.py", line 441, in _run_event
    await coro(*args, **kwargs)
  File "/home/sild/Documents/KaoruBot/src/bot_events.py", line 51, in on_raw_reaction_add
    table_name="reaction_tracker",
  File "/home/sild/Documents/KaoruBot/src/database.py", line 17, in select
    return self.conn.execute(f"SELECT {columns} FROM {table_name} WHERE {where}")
sqlite3.OperationalError: no such column: message_id
[2024-01-08 22:09:03] [ERROR   ] discord.client: Ignoring exception in on_raw_reaction_add
Traceback (most recent call last):
  File "/home/sild/.local/lib/python3.10/site-packages/discord/client.py", line 441, in _run_event
    await coro(*args, **kwargs)
  File "/home/sild/Documents/KaoruBot/src/bot_events.py", line 51, in on_raw_reaction_add
    table_name="reaction_tracker",
  File "/home/sild/Documents/KaoruBot/src/database.py", line 17, in select
    return self.conn.execute(f"SELECT {columns} FROM {table_name} WHERE {where}")
sqlite3.OperationalError: no such column: message_id
[2024-01-08 22:10:28] [ERROR   ] discord.client: Ignoring exception in on_raw_reaction_add
Traceback (most recent call last):
  File "/home/sild/.local/lib/python3.10/site-packages/discord/client.py", line 441, in _run_event
    await coro(*args, **kwargs)
  File "/home/sild/Documents/KaoruBot/src/bot_events.py", line 51, in on_raw_reaction_add
    table_name="reaction_tracker",
  File "/home/sild/Documents/KaoruBot/src/database.py", line 17, in select
    return self.conn.execute(f"SELECT {columns} FROM {table_name} WHERE {where}")
sqlite3.OperationalError: no such column: message_id
[2024-01-08 22:10:55] [ERROR   ] discord.client: Ignoring exception in on_raw_reaction_add
Traceback (most recent call last):
  File "/home/sild/.local/lib/python3.10/site-packages/discord/client.py", line 441, in _run_event
    await coro(*args, **kwargs)
  File "/home/sild/Documents/KaoruBot/src/bot_events.py", line 51, in on_raw_reaction_add
    table_name="reaction_tracker",
  File "/home/sild/Documents/KaoruBot/src/database.py", line 17, in select
    return self.conn.execute(f"SELECT {columns} FROM {table_name} WHERE {where}")
sqlite3.OperationalError: no such column: message_id
[2024-01-08 22:11:04] [ERROR   ] discord.client: Ignoring exception in on_raw_reaction_add
Traceback (most recent call last):
  File "/home/sild/.local/lib/python3.10/site-packages/discord/client.py", line 441, in _run_event
    await coro(*args, **kwargs)
  File "/home/sild/Documents/KaoruBot/src/bot_events.py", line 51, in on_raw_reaction_add
    table_name="reaction_tracker",
  File "/home/sild/Documents/KaoruBot/src/database.py", line 17, in select
    return self.conn.execute(f"SELECT {columns} FROM {table_name} WHERE {where}")
sqlite3.OperationalError: no such column: message_id
[2024-01-08 22:12:57] [ERROR   ] discord.client: Ignoring exception in on_raw_reaction_add
Traceback (most recent call last):
  File "/home/sild/.local/lib/python3.10/site-packages/discord/client.py", line 441, in _run_event
    await coro(*args, **kwargs)
  File "/home/sild/Documents/KaoruBot/src/bot_events.py", line 51, in on_raw_reaction_add
    table_name="reaction_tracker",
  File "/home/sild/Documents/KaoruBot/src/database.py", line 17, in select
    return self.conn.execute(f"SELECT {columns} FROM {table_name} WHERE {where}")
sqlite3.OperationalError: no such column: message_id
[2024-01-08 22:13:00] [ERROR   ] discord.client: Ignoring exception in on_raw_reaction_add
Traceback (most recent call last):
  File "/home/sild/.local/lib/python3.10/site-packages/discord/client.py", line 441, in _run_event
    await coro(*args, **kwargs)
  File "/home/sild/Documents/KaoruBot/src/bot_events.py", line 51, in on_raw_reaction_add
    table_name="reaction_tracker",
  File "/home/sild/Documents/KaoruBot/src/database.py", line 17, in select
    return self.conn.execute(f"SELECT {columns} FROM {table_name} WHERE {where}")
sqlite3.OperationalError: no such column: message_id
[2024-01-08 22:14:37] [ERROR   ] discord.client: Ignoring exception in on_raw_reaction_add
Traceback (most recent call last):
  File "/home/sild/.local/lib/python3.10/site-packages/discord/client.py", line 441, in _run_event
    await coro(*args, **kwargs)
  File "/home/sild/Documents/KaoruBot/src/bot_events.py", line 51, in on_raw_reaction_add
    table_name="reaction_tracker",
  File "/home/sild/Documents/KaoruBot/src/database.py", line 17, in select
    return self.conn.execute(f"SELECT {columns} FROM {table_name} WHERE {where}")
sqlite3.OperationalError: no such column: message_id
[2024-01-08 22:22:43] [ERROR   ] discord.client: Ignoring exception in on_raw_reaction_add
Traceback (most recent call last):
  File "/home/sild/.local/lib/python3.10/site-packages/discord/client.py", line 441, in _run_event
    await coro(*args, **kwargs)
  File "/home/sild/Documents/KaoruBot/src/bot_events.py", line 51, in on_raw_reaction_add
    table_name="reaction_tracker",
  File "/home/sild/Documents/KaoruBot/src/database.py", line 17, in select
    return self.conn.execute(f"SELECT {columns} FROM {table_name} WHERE {where}")
sqlite3.OperationalError: no such column: message_id
[2024-01-08 22:22:45] [ERROR   ] discord.client: Ignoring exception in on_raw_reaction_add
Traceback (most recent call last):
  File "/home/sild/.local/lib/python3.10/site-packages/discord/client.py", line 441, in _run_event
    await coro(*args, **kwargs)
  File "/home/sild/Documents/KaoruBot/src/bot_events.py", line 51, in on_raw_reaction_add
    table_name="reaction_tracker",
  File "/home/sild/Documents/KaoruBot/src/database.py", line 17, in select
    return self.conn.execute(f"SELECT {columns} FROM {table_name} WHERE {where}")
sqlite3.OperationalError: no such column: message_id
[2024-01-08 22:22:50] [ERROR   ] discord.client: Ignoring exception in on_raw_reaction_add
Traceback (most recent call last):
  File "/home/sild/.local/lib/python3.10/site-packages/discord/client.py", line 441, in _run_event
    await coro(*args, **kwargs)
  File "/home/sild/Documents/KaoruBot/src/bot_events.py", line 51, in on_raw_reaction_add
    table_name="reaction_tracker",
  File "/home/sild/Documents/KaoruBot/src/database.py", line 17, in select
    return self.conn.execute(f"SELECT {columns} FROM {table_name} WHERE {where}")
sqlite3.OperationalError: no such column: message_id
[2024-01-08 22:31:21] [ERROR   ] discord.client: Ignoring exception in on_raw_reaction_add
Traceback (most recent call last):
  File "/home/sild/.local/lib/python3.10/site-packages/discord/client.py", line 441, in _run_event
    await coro(*args, **kwargs)
  File "/home/sild/Documents/KaoruBot/src/bot_events.py", line 51, in on_raw_reaction_add
    table_name="reaction_tracker",
  File "/home/sild/Documents/KaoruBot/src/database.py", line 17, in select
    return self.conn.execute(f"SELECT {columns} FROM {table_name} WHERE {where}")
sqlite3.OperationalError: no such column: message_id
[2024-01-08 22:32:26] [ERROR   ] discord.client: Ignoring exception in on_raw_reaction_add
Traceback (most recent call last):
  File "/home/sild/.local/lib/python3.10/site-packages/discord/client.py", line 441, in _run_event
    await coro(*args, **kwargs)
  File "/home/sild/Documents/KaoruBot/src/bot_events.py", line 51, in on_raw_reaction_add
    table_name="reaction_tracker",
  File "/home/sild/Documents/KaoruBot/src/database.py", line 17, in select
    return self.conn.execute(f"SELECT {columns} FROM {table_name} WHERE {where}")
sqlite3.OperationalError: no such column: message_id
[2024-01-08 22:32:29] [ERROR   ] discord.client: Ignoring exception in on_raw_reaction_add
Traceback (most recent call last):
  File "/home/sild/.local/lib/python3.10/site-packages/discord/client.py", line 441, in _run_event
    await coro(*args, **kwargs)
  File "/home/sild/Documents/KaoruBot/src/bot_events.py", line 51, in on_raw_reaction_add
    table_name="reaction_tracker",
  File "/home/sild/Documents/KaoruBot/src/database.py", line 17, in select
    return self.conn.execute(f"SELECT {columns} FROM {table_name} WHERE {where}")
sqlite3.OperationalError: no such column: message_id
[2024-01-08 22:35:04] [ERROR   ] discord.client: Ignoring exception in on_raw_reaction_add
Traceback (most recent call last):
  File "/home/sild/.local/lib/python3.10/site-packages/discord/client.py", line 441, in _run_event
    await coro(*args, **kwargs)
  File "/home/sild/Documents/KaoruBot/src/bot_events.py", line 51, in on_raw_reaction_add
    table_name="reaction_tracker",
  File "/home/sild/Documents/KaoruBot/src/database.py", line 17, in select
    return self.conn.execute(f"SELECT {columns} FROM {table_name} WHERE {where}")
sqlite3.OperationalError: no such column: message_id
[2024-01-08 22:47:23] [ERROR   ] discord.client: Ignoring exception in on_raw_reaction_add
Traceback (most recent call last):
  File "/home/sild/.local/lib/python3.10/site-packages/discord/client.py", line 441, in _run_event
    await coro(*args, **kwargs)
  File "/home/sild/Documents/KaoruBot/src/bot_events.py", line 51, in on_raw_reaction_add
    table_name="reaction_tracker",
  File "/home/sild/Documents/KaoruBot/src/database.py", line 17, in select
    return self.conn.execute(f"SELECT {columns} FROM {table_name} WHERE {where}")
sqlite3.OperationalError: no such column: message_id
[2024-01-08 22:48:12] [ERROR   ] discord.client: Ignoring exception in on_raw_reaction_add
Traceback (most recent call last):
  File "/home/sild/.local/lib/python3.10/site-packages/discord/client.py", line 441, in _run_event
    await coro(*args, **kwargs)
  File "/home/sild/Documents/KaoruBot/src/bot_events.py", line 51, in on_raw_reaction_add
    table_name="reaction_tracker",
  File "/home/sild/Documents/KaoruBot/src/database.py", line 17, in select
    return self.conn.execute(f"SELECT {columns} FROM {table_name} WHERE {where}")
sqlite3.OperationalError: no such column: message_id
[2024-01-08 22:48:50] [INFO    ] discord.gateway: Shard ID None has successfully RESUMED session 455abb0a4e1eb6bc9bda880366c01c6a.
[2024-01-08 22:49:20] [ERROR   ] discord.client: Ignoring exception in on_raw_reaction_add
Traceback (most recent call last):
  File "/home/sild/.local/lib/python3.10/site-packages/discord/client.py", line 441, in _run_event
    await coro(*args, **kwargs)
  File "/home/sild/Documents/KaoruBot/src/bot_events.py", line 51, in on_raw_reaction_add
    table_name="reaction_tracker",
  File "/home/sild/Documents/KaoruBot/src/database.py", line 17, in select
    return self.conn.execute(f"SELECT {columns} FROM {table_name} WHERE {where}")
sqlite3.OperationalError: no such column: message_id
[2024-01-08 22:49:24] [ERROR   ] discord.client: Ignoring exception in on_raw_reaction_add
Traceback (most recent call last):
  File "/home/sild/.local/lib/python3.10/site-packages/discord/client.py", line 441, in _run_event
    await coro(*args, **kwargs)
  File "/home/sild/Documents/KaoruBot/src/bot_events.py", line 51, in on_raw_reaction_add
    table_name="reaction_tracker",
  File "/home/sild/Documents/KaoruBot/src/database.py", line 17, in select
    return self.conn.execute(f"SELECT {columns} FROM {table_name} WHERE {where}")
sqlite3.OperationalError: no such column: message_id
[2024-01-08 22:52:45] [ERROR   ] discord.client: Ignoring exception in on_raw_reaction_add
Traceback (most recent call last):
  File "/home/sild/.local/lib/python3.10/site-packages/discord/client.py", line 441, in _run_event
    await coro(*args, **kwargs)
  File "/home/sild/Documents/KaoruBot/src/bot_events.py", line 51, in on_raw_reaction_add
    table_name="reaction_tracker",
  File "/home/sild/Documents/KaoruBot/src/database.py", line 17, in select
    return self.conn.execute(f"SELECT {columns} FROM {table_name} WHERE {where}")
sqlite3.OperationalError: no such column: message_id
[2024-01-08 22:56:24] [ERROR   ] discord.client: Ignoring exception in on_raw_reaction_add
Traceback (most recent call last):
  File "/home/sild/.local/lib/python3.10/site-packages/discord/client.py", line 441, in _run_event
    await coro(*args, **kwargs)
  File "/home/sild/Documents/KaoruBot/src/bot_events.py", line 51, in on_raw_reaction_add
    table_name="reaction_tracker",
  File "/home/sild/Documents/KaoruBot/src/database.py", line 17, in select
    return self.conn.execute(f"SELECT {columns} FROM {table_name} WHERE {where}")
sqlite3.OperationalError: no such column: message_id
[2024-01-08 22:57:00] [ERROR   ] discord.client: Ignoring exception in on_raw_reaction_add
Traceback (most recent call last):
  File "/home/sild/.local/lib/python3.10/site-packages/discord/client.py", line 441, in _run_event
    await coro(*args, **kwargs)
  File "/home/sild/Documents/KaoruBot/src/bot_events.py", line 51, in on_raw_reaction_add
    table_name="reaction_tracker",
  File "/home/sild/Documents/KaoruBot/src/database.py", line 17, in select
    return self.conn.execute(f"SELECT {columns} FROM {table_name} WHERE {where}")
sqlite3.OperationalError: no such column: message_id
[2024-01-08 23:00:33] [ERROR   ] discord.client: Ignoring exception in on_raw_reaction_add
Traceback (most recent call last):
  File "/home/sild/.local/lib/python3.10/site-packages/discord/client.py", line 441, in _run_event
    await coro(*args, **kwargs)
  File "/home/sild/Documents/KaoruBot/src/bot_events.py", line 51, in on_raw_reaction_add
    table_name="reaction_tracker",
  File "/home/sild/Documents/KaoruBot/src/database.py", line 17, in select
    return self.conn.execute(f"SELECT {columns} FROM {table_name} WHERE {where}")
sqlite3.OperationalError: no such column: message_id
[2024-01-08 23:02:01] [ERROR   ] discord.client: Ignoring exception in on_raw_reaction_add
Traceback (most recent call last):
  File "/home/sild/.local/lib/python3.10/site-packages/discord/client.py", line 441, in _run_event
    await coro(*args, **kwargs)
  File "/home/sild/Documents/KaoruBot/src/bot_events.py", line 51, in on_raw_reaction_add
    table_name="reaction_tracker",
  File "/home/sild/Documents/KaoruBot/src/database.py", line 17, in select
    return self.conn.execute(f"SELECT {columns} FROM {table_name} WHERE {where}")
sqlite3.OperationalError: no such column: message_id
[2024-01-08 23:08:40] [INFO    ] discord.gateway: Shard ID None has successfully RESUMED session 455abb0a4e1eb6bc9bda880366c01c6a.
[2024-01-08 23:23:11] [ERROR   ] discord.client: Ignoring exception in on_raw_reaction_add
Traceback (most recent call last):
  File "/home/sild/.local/lib/python3.10/site-packages/discord/client.py", line 441, in _run_event
    await coro(*args, **kwargs)
  File "/home/sild/Documents/KaoruBot/src/bot_events.py", line 51, in on_raw_reaction_add
    table_name="reaction_tracker",
  File "/home/sild/Documents/KaoruBot/src/database.py", line 17, in select
    return self.conn.execute(f"SELECT {columns} FROM {table_name} WHERE {where}")
sqlite3.OperationalError: no such column: message_id
[2024-01-08 23:30:43] [ERROR   ] discord.client: Ignoring exception in on_raw_reaction_add
Traceback (most recent call last):
  File "/home/sild/.local/lib/python3.10/site-packages/discord/client.py", line 441, in _run_event
    await coro(*args, **kwargs)
  File "/home/sild/Documents/KaoruBot/src/bot_events.py", line 51, in on_raw_reaction_add
    table_name="reaction_tracker",
  File "/home/sild/Documents/KaoruBot/src/database.py", line 17, in select
    return self.conn.execute(f"SELECT {columns} FROM {table_name} WHERE {where}")
sqlite3.OperationalError: no such column: message_id
[2024-01-08 23:31:11] [ERROR   ] discord.client: Ignoring exception in on_raw_reaction_add
Traceback (most recent call last):
  File "/home/sild/.local/lib/python3.10/site-packages/discord/client.py", line 441, in _run_event
    await coro(*args, **kwargs)
  File "/home/sild/Documents/KaoruBot/src/bot_events.py", line 51, in on_raw_reaction_add
    table_name="reaction_tracker",
  File "/home/sild/Documents/KaoruBot/src/database.py", line 17, in select
    return self.conn.execute(f"SELECT {columns} FROM {table_name} WHERE {where}")
sqlite3.OperationalError: no such column: message_id
[2024-01-08 23:31:52] [ERROR   ] discord.client: Ignoring exception in on_raw_reaction_add
Traceback (most recent call last):
  File "/home/sild/.local/lib/python3.10/site-packages/discord/client.py", line 441, in _run_event
    await coro(*args, **kwargs)
  File "/home/sild/Documents/KaoruBot/src/bot_events.py", line 51, in on_raw_reaction_add
    table_name="reaction_tracker",
  File "/home/sild/Documents/KaoruBot/src/database.py", line 17, in select
    return self.conn.execute(f"SELECT {columns} FROM {table_name} WHERE {where}")
sqlite3.OperationalError: no such column: message_id
[2024-01-08 23:32:21] [ERROR   ] discord.client: Ignoring exception in on_raw_reaction_add
Traceback (most recent call last):
  File "/home/sild/.local/lib/python3.10/site-packages/discord/client.py", line 441, in _run_event
    await coro(*args, **kwargs)
  File "/home/sild/Documents/KaoruBot/src/bot_events.py", line 51, in on_raw_reaction_add
    table_name="reaction_tracker",
  File "/home/sild/Documents/KaoruBot/src/database.py", line 17, in select
    return self.conn.execute(f"SELECT {columns} FROM {table_name} WHERE {where}")
sqlite3.OperationalError: no such column: message_id
[2024-01-08 23:48:49] [INFO    ] discord.gateway: Shard ID None has successfully RESUMED session 4a4adf8293b7310704354dcc758cb071.
[2024-01-08 23:54:45] [ERROR   ] discord.client: Ignoring exception in on_raw_reaction_add
Traceback (most recent call last):
  File "/home/sild/.local/lib/python3.10/site-packages/discord/client.py", line 441, in _run_event
    await coro(*args, **kwargs)
  File "/home/sild/Documents/KaoruBot/src/bot_events.py", line 51, in on_raw_reaction_add
    table_name="reaction_tracker",
  File "/home/sild/Documents/KaoruBot/src/database.py", line 17, in select
    return self.conn.execute(f"SELECT {columns} FROM {table_name} WHERE {where}")
sqlite3.OperationalError: no such column: message_id
[2024-01-09 00:00:15] [ERROR   ] discord.client: Ignoring exception in on_raw_reaction_add
Traceback (most recent call last):
  File "/home/sild/.local/lib/python3.10/site-packages/discord/client.py", line 441, in _run_event
    await coro(*args, **kwargs)
  File "/home/sild/Documents/KaoruBot/src/bot_events.py", line 51, in on_raw_reaction_add
    table_name="reaction_tracker",
  File "/home/sild/Documents/KaoruBot/src/database.py", line 17, in select
    return self.conn.execute(f"SELECT {columns} FROM {table_name} WHERE {where}")
sqlite3.OperationalError: no such column: message_id
[2024-01-09 00:05:30] [ERROR   ] discord.client: Ignoring exception in on_raw_reaction_add
Traceback (most recent call last):
  File "/home/sild/.local/lib/python3.10/site-packages/discord/client.py", line 441, in _run_event
    await coro(*args, **kwargs)
  File "/home/sild/Documents/KaoruBot/src/bot_events.py", line 51, in on_raw_reaction_add
    table_name="reaction_tracker",
  File "/home/sild/Documents/KaoruBot/src/database.py", line 17, in select
    return self.conn.execute(f"SELECT {columns} FROM {table_name} WHERE {where}")
sqlite3.OperationalError: no such column: message_id
[2024-01-09 00:08:12] [ERROR   ] discord.client: Ignoring exception in on_raw_reaction_add
Traceback (most recent call last):
  File "/home/sild/.local/lib/python3.10/site-packages/discord/client.py", line 441, in _run_event
    await coro(*args, **kwargs)
  File "/home/sild/Documents/KaoruBot/src/bot_events.py", line 51, in on_raw_reaction_add
    table_name="reaction_tracker",
  File "/home/sild/Documents/KaoruBot/src/database.py", line 17, in select
    return self.conn.execute(f"SELECT {columns} FROM {table_name} WHERE {where}")
sqlite3.OperationalError: no such column: message_id
[2024-01-09 00:09:43] [ERROR   ] discord.client: Ignoring exception in on_raw_reaction_add
Traceback (most recent call last):
  File "/home/sild/.local/lib/python3.10/site-packages/discord/client.py", line 441, in _run_event
    await coro(*args, **kwargs)
  File "/home/sild/Documents/KaoruBot/src/bot_events.py", line 51, in on_raw_reaction_add
    table_name="reaction_tracker",
  File "/home/sild/Documents/KaoruBot/src/database.py", line 17, in select
    return self.conn.execute(f"SELECT {columns} FROM {table_name} WHERE {where}")
sqlite3.OperationalError: no such column: message_id
[2024-01-09 00:10:37] [ERROR   ] discord.client: Ignoring exception in on_raw_reaction_add
Traceback (most recent call last):
  File "/home/sild/.local/lib/python3.10/site-packages/discord/client.py", line 441, in _run_event
    await coro(*args, **kwargs)
  File "/home/sild/Documents/KaoruBot/src/bot_events.py", line 51, in on_raw_reaction_add
    table_name="reaction_tracker",
  File "/home/sild/Documents/KaoruBot/src/database.py", line 17, in select
    return self.conn.execute(f"SELECT {columns} FROM {table_name} WHERE {where}")
sqlite3.OperationalError: no such column: message_id
[2024-01-09 00:11:46] [ERROR   ] discord.client: Ignoring exception in on_raw_reaction_add
Traceback (most recent call last):
  File "/home/sild/.local/lib/python3.10/site-packages/discord/client.py", line 441, in _run_event
    await coro(*args, **kwargs)
  File "/home/sild/Documents/KaoruBot/src/bot_events.py", line 51, in on_raw_reaction_add
    table_name="reaction_tracker",
  File "/home/sild/Documents/KaoruBot/src/database.py", line 17, in select
    return self.conn.execute(f"SELECT {columns} FROM {table_name} WHERE {where}")
sqlite3.OperationalError: no such column: message_id
[2024-01-09 00:13:30] [ERROR   ] discord.client: Ignoring exception in on_raw_reaction_add
Traceback (most recent call last):
  File "/home/sild/.local/lib/python3.10/site-packages/discord/client.py", line 441, in _run_event
    await coro(*args, **kwargs)
  File "/home/sild/Documents/KaoruBot/src/bot_events.py", line 51, in on_raw_reaction_add
    table_name="reaction_tracker",
  File "/home/sild/Documents/KaoruBot/src/database.py", line 17, in select
    return self.conn.execute(f"SELECT {columns} FROM {table_name} WHERE {where}")
sqlite3.OperationalError: no such column: message_id
[2024-01-09 00:14:18] [ERROR   ] discord.client: Ignoring exception in on_raw_reaction_add
Traceback (most recent call last):
  File "/home/sild/.local/lib/python3.10/site-packages/discord/client.py", line 441, in _run_event
    await coro(*args, **kwargs)
  File "/home/sild/Documents/KaoruBot/src/bot_events.py", line 51, in on_raw_reaction_add
    table_name="reaction_tracker",
  File "/home/sild/Documents/KaoruBot/src/database.py", line 17, in select
    return self.conn.execute(f"SELECT {columns} FROM {table_name} WHERE {where}")
sqlite3.OperationalError: no such column: message_id
[2024-01-09 00:14:47] [ERROR   ] discord.client: Ignoring exception in on_raw_reaction_add
Traceback (most recent call last):
  File "/home/sild/.local/lib/python3.10/site-packages/discord/client.py", line 441, in _run_event
    await coro(*args, **kwargs)
  File "/home/sild/Documents/KaoruBot/src/bot_events.py", line 51, in on_raw_reaction_add
    table_name="reaction_tracker",
  File "/home/sild/Documents/KaoruBot/src/database.py", line 17, in select
    return self.conn.execute(f"SELECT {columns} FROM {table_name} WHERE {where}")
sqlite3.OperationalError: no such column: message_id
[2024-01-09 00:17:54] [ERROR   ] discord.client: Ignoring exception in on_raw_reaction_add
Traceback (most recent call last):
  File "/home/sild/.local/lib/python3.10/site-packages/discord/client.py", line 441, in _run_event
    await coro(*args, **kwargs)
  File "/home/sild/Documents/KaoruBot/src/bot_events.py", line 51, in on_raw_reaction_add
    table_name="reaction_tracker",
  File "/home/sild/Documents/KaoruBot/src/database.py", line 17, in select
    return self.conn.execute(f"SELECT {columns} FROM {table_name} WHERE {where}")
sqlite3.OperationalError: no such column: message_id
[2024-01-09 00:18:41] [ERROR   ] discord.client: Ignoring exception in on_raw_reaction_add
Traceback (most recent call last):
  File "/home/sild/.local/lib/python3.10/site-packages/discord/client.py", line 441, in _run_event
    await coro(*args, **kwargs)
  File "/home/sild/Documents/KaoruBot/src/bot_events.py", line 51, in on_raw_reaction_add
    table_name="reaction_tracker",
  File "/home/sild/Documents/KaoruBot/src/database.py", line 17, in select
    return self.conn.execute(f"SELECT {columns} FROM {table_name} WHERE {where}")
sqlite3.OperationalError: no such column: message_id
[2024-01-09 00:18:52] [ERROR   ] discord.client: Ignoring exception in on_raw_reaction_add
Traceback (most recent call last):
  File "/home/sild/.local/lib/python3.10/site-packages/discord/client.py", line 441, in _run_event
    await coro(*args, **kwargs)
  File "/home/sild/Documents/KaoruBot/src/bot_events.py", line 51, in on_raw_reaction_add
    table_name="reaction_tracker",
  File "/home/sild/Documents/KaoruBot/src/database.py", line 17, in select
    return self.conn.execute(f"SELECT {columns} FROM {table_name} WHERE {where}")
sqlite3.OperationalError: no such column: message_id
[2024-01-09 18:56:18] [INFO    ] discord.client: logging in using static token
[2024-01-09 18:56:19] [INFO    ] discord.gateway: Shard ID None has connected to Gateway (Session ID: e0bc2769d42664c9a72e250b0bc380d4).
[2024-01-09 18:56:21] [INFO    ] root: Bot is ready.
[2024-01-09 19:35:54] [ERROR   ] discord.client: Attempting a reconnect in 0.75s
Traceback (most recent call last):
  File "/home/sild/.local/lib/python3.10/site-packages/discord/client.py", line 659, in connect
    await self.ws.poll_event()
  File "/home/sild/.local/lib/python3.10/site-packages/discord/gateway.py", line 646, in poll_event
    raise ConnectionClosed(self.socket, shard_id=self.shard_id, code=code) from None
discord.errors.ConnectionClosed: Shard ID None WebSocket closed with 1000
[2024-01-09 19:35:56] [INFO    ] discord.gateway: Shard ID None has successfully RESUMED session e0bc2769d42664c9a72e250b0bc380d4.
[2024-01-09 22:19:05] [WARNING ] discord.gateway: Can't keep up, shard ID None websocket is 13.5s behind.
[2024-01-09 22:51:44] [INFO    ] discord.gateway: Shard ID None has successfully RESUMED session e0bc2769d42664c9a72e250b0bc380d4.
[2024-01-09 23:01:39] [INFO    ] discord.gateway: Shard ID None has successfully RESUMED session e0bc2769d42664c9a72e250b0bc380d4.
[2024-01-09 23:24:21] [ERROR   ] discord.app_commands.tree: Ignoring exception in command tree
Traceback (most recent call last):
  File "/home/sild/.local/lib/python3.10/site-packages/discord/app_commands/tree.py", line 1089, in wrapper
    await self._call(interaction)
  File "/home/sild/.local/lib/python3.10/site-packages/discord/app_commands/tree.py", line 1221, in _call
    command, options = self._get_app_command_options(data)
  File "/home/sild/.local/lib/python3.10/site-packages/discord/app_commands/tree.py", line 1125, in _get_app_command_options
    raise CommandNotFound(name, parents)
discord.app_commands.errors.CommandNotFound: Application command 'ss' not found
[2024-01-10 16:11:55] [INFO    ] discord.client: logging in using static token
[2024-01-10 16:11:56] [INFO    ] discord.gateway: Shard ID None has connected to Gateway (Session ID: 005358957bcf66a68a1c9a59c4dae746).
[2024-01-10 16:11:58] [INFO    ] root: Bot is ready.
[2024-01-10 16:13:46] [INFO    ] discord.client: logging in using static token
[2024-01-10 16:13:48] [INFO    ] discord.gateway: Shard ID None has connected to Gateway (Session ID: 18d7ef70b5d4a06491258f09e05f287a).
[2024-01-10 16:13:50] [INFO    ] root: Bot is ready.
[2024-01-10 16:15:00] [INFO    ] discord.client: logging in using static token
[2024-01-10 16:15:02] [INFO    ] discord.gateway: Shard ID None has connected to Gateway (Session ID: 9fd1ab80f8e6afcd6920c224141a7660).
[2024-01-10 16:15:04] [INFO    ] root: Bot is ready.
[2024-01-10 16:18:09] [INFO    ] discord.client: logging in using static token
[2024-01-10 16:18:10] [INFO    ] discord.gateway: Shard ID None has connected to Gateway (Session ID: a3f98028c13bfd5b4cccdd77242b9e59).
[2024-01-10 16:18:12] [INFO    ] root: Bot is ready.
[2024-01-10 16:18:27] [INFO    ] discord.client: logging in using static token
[2024-01-10 16:18:29] [INFO    ] discord.gateway: Shard ID None has connected to Gateway (Session ID: 2aa4e3f67b99fc191d7b4db51b7f64f9).
[2024-01-10 16:18:31] [INFO    ] root: Bot is ready.
[2024-01-10 16:23:01] [INFO    ] discord.client: logging in using static token
[2024-01-10 16:23:02] [INFO    ] discord.gateway: Shard ID None has connected to Gateway (Session ID: 633070af98950cf80bafa305f7356b94).
[2024-01-10 16:23:04] [INFO    ] root: Bot is ready.
[2024-01-10 16:23:14] [ERROR   ] discord.app_commands.tree: Ignoring exception in command 'selfmute'
Traceback (most recent call last):
  File "/home/sild/.local/lib/python3.10/site-packages/discord/app_commands/commands.py", line 827, in _do_call
    return await self._callback(self.binding, interaction, **params)  # type: ignore
  File "/home/sild/Documents/KaoruBot/src/bot_commands.py", line 44, in selfmute
    self.bot.database.insert_or_update(
  File "/home/sild/Documents/KaoruBot/src/database.py", line 13, in insert
    self.conn.execute(f"INSERT INTO {table_name} ({columns}) VALUES ({values})")
sqlite3.IntegrityError: UNIQUE constraint failed: muted_users.user_id

The above exception was the direct cause of the following exception:

Traceback (most recent call last):
  File "/home/sild/.local/lib/python3.10/site-packages/discord/app_commands/tree.py", line 1248, in _call
    await command._invoke_with_namespace(interaction, namespace)
  File "/home/sild/.local/lib/python3.10/site-packages/discord/app_commands/commands.py", line 853, in _invoke_with_namespace
    return await self._do_call(interaction, transformed_values)
  File "/home/sild/.local/lib/python3.10/site-packages/discord/app_commands/commands.py", line 846, in _do_call
    raise CommandInvokeError(self, e) from e
discord.app_commands.errors.CommandInvokeError: Command 'selfmute' raised an exception: IntegrityError: UNIQUE constraint failed: muted_users.user_id
[2024-01-10 16:24:51] [INFO    ] discord.client: logging in using static token
[2024-01-10 16:24:52] [INFO    ] discord.gateway: Shard ID None has connected to Gateway (Session ID: cba05cf2170e4a6443889724f34552f0).
[2024-01-10 16:24:54] [INFO    ] root: Bot is ready.
[2024-01-10 16:27:35] [INFO    ] discord.client: logging in using static token
[2024-01-10 16:27:35] [INFO    ] discord.gateway: Shard ID None has connected to Gateway (Session ID: 3555fe571dd73afbd1f204103f70f867).
[2024-01-10 16:27:38] [INFO    ] root: Bot is ready.
[2024-01-10 16:40:07] [INFO    ] discord.client: logging in using static token
[2024-01-10 16:40:09] [INFO    ] discord.gateway: Shard ID None has connected to Gateway (Session ID: 007d353ff0b8b8ab02ce6980ab8cad33).
[2024-01-10 16:40:11] [INFO    ] root: Bot is ready.
[2024-01-10 16:40:52] [INFO    ] discord.client: logging in using static token
[2024-01-10 16:40:53] [INFO    ] discord.gateway: Shard ID None has connected to Gateway (Session ID: 9c95308fcf6bfc2e1c7aa8cff3c6f92b).
[2024-01-10 16:48:03] [INFO    ] discord.client: logging in using static token
[2024-01-10 16:48:04] [INFO    ] discord.gateway: Shard ID None has connected to Gateway (Session ID: 4667beb14daf8fa1fc66349c4b05514f).
[2024-01-10 16:48:06] [INFO    ] root: Bot is ready.
[2024-01-10 16:48:22] [INFO    ] discord.client: logging in using static token
[2024-01-10 16:48:23] [INFO    ] discord.gateway: Shard ID None has connected to Gateway (Session ID: 10f6065f9c722dbe83e742d57cad28c9).
[2024-01-10 16:48:25] [INFO    ] root: Bot is ready.
[2024-01-10 16:53:36] [INFO    ] discord.client: logging in using static token
[2024-01-10 16:53:37] [INFO    ] discord.gateway: Shard ID None has connected to Gateway (Session ID: 4c4426b36ceb4c446b5b6b9abb1d31f5).
[2024-01-10 16:53:39] [INFO    ] root: Bot is ready.
[2024-01-10 16:57:17] [INFO    ] discord.client: logging in using static token
[2024-01-10 16:57:18] [INFO    ] discord.gateway: Shard ID None has connected to Gateway (Session ID: 262a380bac58184e8364487a5ee5478c).
[2024-01-10 16:57:20] [INFO    ] root: Bot is ready.
[2024-01-10 16:58:05] [INFO    ] discord.client: logging in using static token
[2024-01-10 16:58:06] [INFO    ] discord.gateway: Shard ID None has connected to Gateway (Session ID: 80f9d50be453f653cb6ac45d68efb54c).
[2024-01-10 16:58:08] [INFO    ] root: Bot is ready.
[2024-01-10 16:58:22] [INFO    ] discord.client: logging in using static token
[2024-01-10 16:58:23] [INFO    ] discord.gateway: Shard ID None has connected to Gateway (Session ID: 883764a417c14da675827518af4bc47e).
[2024-01-10 16:58:26] [INFO    ] root: Bot is ready.
[2024-01-10 16:59:14] [INFO    ] discord.client: logging in using static token
[2024-01-10 16:59:15] [INFO    ] discord.gateway: Shard ID None has connected to Gateway (Session ID: 36a526ee5053485adbeecf313c5c4d92).
[2024-01-10 16:59:17] [INFO    ] root: Bot is ready.
[2024-01-10 17:01:36] [INFO    ] discord.client: logging in using static token
[2024-01-10 17:01:38] [INFO    ] discord.gateway: Shard ID None has connected to Gateway (Session ID: deac25922709ef8f4d32357b25a037c7).
[2024-01-10 17:01:40] [INFO    ] root: Bot is ready.
[2024-01-10 17:02:57] [INFO    ] discord.client: logging in using static token
[2024-01-10 17:02:58] [INFO    ] discord.gateway: Shard ID None has connected to Gateway (Session ID: 084d629d50305d4720c44b493f7554df).
[2024-01-10 17:03:00] [INFO    ] root: Bot is ready.
[2024-01-10 17:04:06] [INFO    ] discord.client: logging in using static token
[2024-01-10 17:04:07] [INFO    ] discord.gateway: Shard ID None has connected to Gateway (Session ID: bf4c7f1ff63410d5efb4c0ce1dc67b34).
[2024-01-10 17:04:09] [INFO    ] root: Bot is ready.
[2024-01-10 17:05:06] [INFO    ] discord.client: logging in using static token
[2024-01-10 17:05:07] [INFO    ] discord.gateway: Shard ID None has connected to Gateway (Session ID: a57162660a096178b54ebc153a97ed7f).
[2024-01-10 17:05:09] [INFO    ] root: Bot is ready.
[2024-01-10 17:05:29] [ERROR   ] discord.app_commands.tree: Ignoring exception in command 'unmute'
Traceback (most recent call last):
  File "/home/sild/.local/lib/python3.10/site-packages/discord/app_commands/commands.py", line 827, in _do_call
    return await self._callback(self.binding, interaction, **params)  # type: ignore
  File "/home/sild/Documents/KaoruBot/src/bot_commands.py", line 45, in unmute_user
    muted_user = data_types.MutedUser(muted_user)
  File "/home/sild/Documents/KaoruBot/src/data_types.py", line 17, in __init__
    self.user_id = muted_user[0]
TypeError: 'sqlite3.Cursor' object is not subscriptable

The above exception was the direct cause of the following exception:

Traceback (most recent call last):
  File "/home/sild/.local/lib/python3.10/site-packages/discord/app_commands/tree.py", line 1248, in _call
    await command._invoke_with_namespace(interaction, namespace)
  File "/home/sild/.local/lib/python3.10/site-packages/discord/app_commands/commands.py", line 853, in _invoke_with_namespace
    return await self._do_call(interaction, transformed_values)
  File "/home/sild/.local/lib/python3.10/site-packages/discord/app_commands/commands.py", line 842, in _do_call
    raise CommandInvokeError(self, e) from e
discord.app_commands.errors.CommandInvokeError: Command 'unmute' raised an exception: TypeError: 'sqlite3.Cursor' object is not subscriptable
[2024-01-10 17:05:54] [INFO    ] discord.client: logging in using static token
[2024-01-10 17:05:55] [INFO    ] discord.gateway: Shard ID None has connected to Gateway (Session ID: cd0f27302c529494b892ee444c62ef83).
[2024-01-10 17:05:57] [INFO    ] root: Bot is ready.
[2024-01-10 17:06:00] [ERROR   ] discord.app_commands.tree: Ignoring exception in command 'unmute'
Traceback (most recent call last):
  File "/home/sild/.local/lib/python3.10/site-packages/discord/app_commands/commands.py", line 827, in _do_call
    return await self._callback(self.binding, interaction, **params)  # type: ignore
  File "/home/sild/Documents/KaoruBot/src/bot_commands.py", line 45, in unmute_user
    muted_user = data_types.MutedUser(muted_user[0])
TypeError: 'sqlite3.Cursor' object is not subscriptable

The above exception was the direct cause of the following exception:

Traceback (most recent call last):
  File "/home/sild/.local/lib/python3.10/site-packages/discord/app_commands/tree.py", line 1248, in _call
    await command._invoke_with_namespace(interaction, namespace)
  File "/home/sild/.local/lib/python3.10/site-packages/discord/app_commands/commands.py", line 853, in _invoke_with_namespace
    return await self._do_call(interaction, transformed_values)
  File "/home/sild/.local/lib/python3.10/site-packages/discord/app_commands/commands.py", line 842, in _do_call
    raise CommandInvokeError(self, e) from e
discord.app_commands.errors.CommandInvokeError: Command 'unmute' raised an exception: TypeError: 'sqlite3.Cursor' object is not subscriptable
[2024-01-10 17:07:26] [INFO    ] discord.client: logging in using static token
[2024-01-10 17:07:27] [INFO    ] discord.gateway: Shard ID None has connected to Gateway (Session ID: c2a07108cff086413610f52fd064fade).
[2024-01-10 17:07:29] [INFO    ] root: Bot is ready.
[2024-01-10 17:07:32] [ERROR   ] discord.app_commands.tree: Ignoring exception in command 'unmute'
Traceback (most recent call last):
  File "/home/sild/.local/lib/python3.10/site-packages/discord/app_commands/commands.py", line 827, in _do_call
    return await self._callback(self.binding, interaction, **params)  # type: ignore
  File "/home/sild/Documents/KaoruBot/src/bot_commands.py", line 45, in unmute_user
    if len(muted_user) == 0:
TypeError: object of type 'sqlite3.Cursor' has no len()

The above exception was the direct cause of the following exception:

Traceback (most recent call last):
  File "/home/sild/.local/lib/python3.10/site-packages/discord/app_commands/tree.py", line 1248, in _call
    await command._invoke_with_namespace(interaction, namespace)
  File "/home/sild/.local/lib/python3.10/site-packages/discord/app_commands/commands.py", line 853, in _invoke_with_namespace
    return await self._do_call(interaction, transformed_values)
  File "/home/sild/.local/lib/python3.10/site-packages/discord/app_commands/commands.py", line 842, in _do_call
    raise CommandInvokeError(self, e) from e
discord.app_commands.errors.CommandInvokeError: Command 'unmute' raised an exception: TypeError: object of type 'sqlite3.Cursor' has no len()
[2024-01-10 17:08:52] [INFO    ] discord.client: logging in using static token
[2024-01-10 17:08:53] [INFO    ] discord.gateway: Shard ID None has connected to Gateway (Session ID: 5b72fbd9f288f52f73b57abbc9846520).
[2024-01-10 17:08:55] [INFO    ] root: Bot is ready.
[2024-01-10 17:16:19] [ERROR   ] discord.client: Attempting a reconnect in 1.49s
Traceback (most recent call last):
  File "/home/sild/.local/lib/python3.10/site-packages/discord/client.py", line 659, in connect
    await self.ws.poll_event()
  File "/home/sild/.local/lib/python3.10/site-packages/discord/gateway.py", line 646, in poll_event
    raise ConnectionClosed(self.socket, shard_id=self.shard_id, code=code) from None
discord.errors.ConnectionClosed: Shard ID None WebSocket closed with 1000
[2024-01-10 17:16:21] [INFO    ] discord.gateway: Shard ID None has successfully RESUMED session 5b72fbd9f288f52f73b57abbc9846520.
[2024-01-10 17:39:30] [INFO    ] discord.gateway: Shard ID None has successfully RESUMED session 5b72fbd9f288f52f73b57abbc9846520.
[2024-01-10 17:56:16] [INFO    ] discord.client: logging in using static token
[2024-01-10 17:56:17] [INFO    ] discord.gateway: Shard ID None has connected to Gateway (Session ID: 34f83db9c7706a2a10b755d21f9314c7).
[2024-01-10 17:56:19] [INFO    ] root: Bot is ready.
[2024-01-10 17:57:52] [ERROR   ] discord.app_commands.tree: Ignoring exception in command 'attach_new_role_to_reaction'
Traceback (most recent call last):
  File "/home/sild/.local/lib/python3.10/site-packages/discord/app_commands/commands.py", line 827, in _do_call
    return await self._callback(self.binding, interaction, **params)  # type: ignore
  File "/home/sild/Documents/KaoruBot/src/bot_commands.py", line 140, in attach_new_role_to_reaction
    message = await interaction.channel.fetch_message(message_id)
  File "/home/sild/.local/lib/python3.10/site-packages/discord/abc.py", line 1624, in fetch_message
    data = await self._state.http.get_message(channel.id, id)
  File "/home/sild/.local/lib/python3.10/site-packages/discord/http.py", line 741, in request
    raise NotFound(response, data)
discord.errors.NotFound: 404 Not Found (error code: 10008): Unknown Message

The above exception was the direct cause of the following exception:

Traceback (most recent call last):
  File "/home/sild/.local/lib/python3.10/site-packages/discord/app_commands/tree.py", line 1248, in _call
    await command._invoke_with_namespace(interaction, namespace)
  File "/home/sild/.local/lib/python3.10/site-packages/discord/app_commands/commands.py", line 853, in _invoke_with_namespace
    return await self._do_call(interaction, transformed_values)
  File "/home/sild/.local/lib/python3.10/site-packages/discord/app_commands/commands.py", line 846, in _do_call
    raise CommandInvokeError(self, e) from e
discord.app_commands.errors.CommandInvokeError: Command 'attach_new_role_to_reaction' raised an exception: NotFound: 404 Not Found (error code: 10008): Unknown Message
[2024-01-10 17:59:53] [INFO    ] discord.client: logging in using static token
[2024-01-10 17:59:54] [INFO    ] discord.gateway: Shard ID None has connected to Gateway (Session ID: 0a32f04877a643641f3014eed7c66b98).
[2024-01-10 17:59:56] [INFO    ] root: Bot is ready.
[2024-01-10 18:02:01] [INFO    ] discord.client: logging in using static token
[2024-01-10 18:02:02] [INFO    ] discord.gateway: Shard ID None has connected to Gateway (Session ID: 0714144f2cc80c7f36db631b5037ad9f).
[2024-01-10 18:02:04] [INFO    ] root: Bot is ready.
[2024-01-10 18:02:23] [INFO    ] discord.client: logging in using static token
[2024-01-10 18:02:24] [INFO    ] discord.gateway: Shard ID None has connected to Gateway (Session ID: 9cfa9d6331c83dc5d5a48c0d5d96f557).
[2024-01-10 18:02:26] [INFO    ] root: Bot is ready.
[2024-01-10 18:03:05] [INFO    ] discord.client: logging in using static token
[2024-01-10 18:03:06] [INFO    ] discord.gateway: Shard ID None has connected to Gateway (Session ID: 66824e7f1878b9e1acfefc20a09ce60b).
[2024-01-10 18:03:08] [INFO    ] root: Bot is ready.
[2024-01-10 18:03:57] [INFO    ] discord.client: logging in using static token
[2024-01-10 18:03:58] [INFO    ] discord.gateway: Shard ID None has connected to Gateway (Session ID: dfb571a62ba733500caa0e50bd4aff70).
[2024-01-10 18:04:00] [INFO    ] root: Bot is ready.
[2024-01-10 18:05:20] [INFO    ] discord.client: logging in using static token
[2024-01-10 18:05:21] [INFO    ] discord.gateway: Shard ID None has connected to Gateway (Session ID: 2623ef566fa967548cdb89a6343aea09).
[2024-01-10 18:05:23] [INFO    ] root: Bot is ready.
[2024-01-10 18:07:01] [INFO    ] discord.client: logging in using static token
[2024-01-10 18:07:02] [INFO    ] discord.gateway: Shard ID None has connected to Gateway (Session ID: ab550436a5a9b06492bc3b4b76a84150).
[2024-01-10 18:07:04] [INFO    ] root: Bot is ready.
[2024-01-10 18:07:56] [INFO    ] discord.client: logging in using static token
[2024-01-10 18:07:57] [INFO    ] discord.gateway: Shard ID None has connected to Gateway (Session ID: 3c9aa4931dafa9504fc9026834ba4193).
[2024-01-10 18:07:59] [INFO    ] root: Bot is ready.
[2024-01-10 18:08:07] [INFO    ] discord.client: logging in using static token
[2024-01-10 18:08:08] [INFO    ] discord.gateway: Shard ID None has connected to Gateway (Session ID: f8a43e3a00cb15c322559e120fc7f987).
[2024-01-10 18:08:10] [INFO    ] root: Bot is ready.
[2024-01-10 18:08:41] [INFO    ] discord.client: logging in using static token
[2024-01-10 18:08:42] [INFO    ] discord.gateway: Shard ID None has connected to Gateway (Session ID: 50a0cfdbd583db953fe0946b69a5a6cd).
[2024-01-10 18:08:44] [INFO    ] root: Bot is ready.
[2024-01-10 18:09:19] [INFO    ] discord.client: logging in using static token
[2024-01-10 18:09:20] [INFO    ] discord.gateway: Shard ID None has connected to Gateway (Session ID: 46fdf19f9dee4c684cd78ca2aa72c305).
[2024-01-10 18:09:22] [INFO    ] root: Bot is ready.
[2024-01-10 18:09:45] [INFO    ] discord.client: logging in using static token
[2024-01-10 18:09:46] [INFO    ] discord.gateway: Shard ID None has connected to Gateway (Session ID: 79c634c4e71f5505550d86976ece8a77).
[2024-01-10 18:09:48] [INFO    ] root: Bot is ready.
[2024-01-10 18:10:03] [INFO    ] discord.client: logging in using static token
[2024-01-10 18:10:04] [INFO    ] discord.gateway: Shard ID None has connected to Gateway (Session ID: 54eeb2224c4bfcf231cab6f7726b5338).
[2024-01-10 18:10:06] [INFO    ] root: Bot is ready.
[2024-01-10 18:10:07] [ERROR   ] discord.client: Ignoring exception in on_raw_reaction_add
Traceback (most recent call last):
  File "/home/sild/.local/lib/python3.10/site-packages/discord/client.py", line 441, in _run_event
    await coro(*args, **kwargs)
  File "/home/sild/Documents/KaoruBot/src/bot_events.py", line 56, in on_raw_reaction_add
    await handle_reaction_role_add(self, payload)
  File "/home/sild/Documents/KaoruBot/src/bot_events.py", line 19, in handle_reaction_role_add
    print(reaction_emoji.strip() == payload.emoji.strip())
AttributeError: 'PartialEmoji' object has no attribute 'strip'
[2024-01-10 18:10:19] [ERROR   ] discord.client: Ignoring exception in on_raw_reaction_add
Traceback (most recent call last):
  File "/home/sild/.local/lib/python3.10/site-packages/discord/client.py", line 441, in _run_event
    await coro(*args, **kwargs)
  File "/home/sild/Documents/KaoruBot/src/bot_events.py", line 56, in on_raw_reaction_add
    await handle_reaction_role_add(self, payload)
  File "/home/sild/Documents/KaoruBot/src/bot_events.py", line 19, in handle_reaction_role_add
    print(reaction_emoji.strip() == payload.emoji.strip())
AttributeError: 'PartialEmoji' object has no attribute 'strip'
[2024-01-10 18:10:56] [ERROR   ] discord.client: Ignoring exception in on_raw_reaction_add
Traceback (most recent call last):
  File "/home/sild/.local/lib/python3.10/site-packages/discord/client.py", line 441, in _run_event
    await coro(*args, **kwargs)
  File "/home/sild/Documents/KaoruBot/src/bot_events.py", line 56, in on_raw_reaction_add
    await handle_reaction_role_add(self, payload)
  File "/home/sild/Documents/KaoruBot/src/bot_events.py", line 19, in handle_reaction_role_add
    print(reaction_emoji.strip() == payload.emoji.strip())
AttributeError: 'PartialEmoji' object has no attribute 'strip'
[2024-01-10 18:11:18] [INFO    ] discord.client: logging in using static token
[2024-01-10 18:11:19] [INFO    ] discord.gateway: Shard ID None has connected to Gateway (Session ID: 5db4b00b904b6925d436a2808eaf6395).
[2024-01-10 18:11:21] [INFO    ] root: Bot is ready.
[2024-01-10 18:11:22] [ERROR   ] discord.client: Ignoring exception in on_raw_reaction_add
Traceback (most recent call last):
  File "/home/sild/.local/lib/python3.10/site-packages/discord/client.py", line 441, in _run_event
    await coro(*args, **kwargs)
  File "/home/sild/Documents/KaoruBot/src/bot_events.py", line 57, in on_raw_reaction_add
    await handle_reaction_role_add(self, payload)
  File "/home/sild/Documents/KaoruBot/src/bot_events.py", line 20, in handle_reaction_role_add
    print(reaction_emoji.strip() == payload.emoji.strip())
AttributeError: 'PartialEmoji' object has no attribute 'strip'
[2024-01-10 18:11:46] [INFO    ] discord.client: logging in using static token
[2024-01-10 18:11:47] [INFO    ] discord.gateway: Shard ID None has connected to Gateway (Session ID: 62c28609e30188208a32cbd3637fc081).
[2024-01-10 18:11:49] [INFO    ] root: Bot is ready.
[2024-01-10 18:12:10] [INFO    ] discord.client: logging in using static token
[2024-01-10 18:12:11] [INFO    ] discord.gateway: Shard ID None has connected to Gateway (Session ID: cce2199aac3206581ea885ede6850c3f).
[2024-01-10 18:12:13] [INFO    ] root: Bot is ready.
[2024-01-10 18:17:35] [INFO    ] discord.client: logging in using static token
[2024-01-10 18:17:36] [INFO    ] discord.gateway: Shard ID None has connected to Gateway (Session ID: 7fe021dfd02e8d3e7b2973a111250951).
[2024-01-10 18:17:38] [INFO    ] root: Bot is ready.
[2024-01-10 18:29:32] [INFO    ] discord.client: logging in using static token
[2024-01-10 18:29:33] [INFO    ] discord.gateway: Shard ID None has connected to Gateway (Session ID: 31c6a2379f32014b70c589a64e81fb5e).
[2024-01-10 18:29:35] [INFO    ] root: Bot is ready.
